Workbook

Sheet 01 DATOS PERSONALES
A1: ORGANIZACION_POLITICA | B1: DNI_CANDIDATO | C1: CANDIDATO | D1: DOCUMENTO_IDENTIDAD | E1: APELLIDO_PATERNO | F1: APELLIDO_MATERNO | G1: NOMBRES | H1: SEXO | I1: FECHA_NACIMIENTO | J1: PAIS_NACIMIENTO | K1: DEPARTAMENTO_NACIMIENTO | L1: PROVINCIA_NACIMIENTO | M1: DISTRITO_NACIMIENTO | N1: PRIMER_CARGO_ELECCION | O1: SEGUNDO_CARGO_ELECION | P1: DISTRITO_ELEC | Q1: INFORMACION_COMPLEMENTARIA | R1: URL_FOTO | S1: TXRUTAVIRTUAL | T1: TXNOMBREDOCUMENTO | U1: EDAD | V1: RANGO_EDAD | W1: PAÍS_LIMPIO | X1: SEXO_LIMPIO | Y1: DEP_NAC_LIMPIO | Z1: DISTRITO_ELEC_LIMPIO
A2: AHORA NACION - AN | B2: 29569533 | C2: ARMINTA VALENCIA, MARLENY BIBIANA | D2: 29569533 | E2: ARMINTA | F2: VALENCIA | G2: MARLENY BIBIANA | H2: FEMENINO | I2: 17/12/1967 | J2: PERÚ | K2: AREQUIPA | L2: AREQUIPA | M2: AREQUIPA | N2: DIPUTADO | P2: AREQUIPA | R2: https://mpesije.jne.gob.pe/apidocs/1d29caa5-9573-43f8-b661-c8bcdcb459d0.jpeg | S2: https://mpesije.jne.gob.pe/apidocs/257db15e-d676-4f48-a881-33b94bc75df8.pdf | T2: =CONCATENATE(A20," - ",B20,".pdf") -> FUERZA POPULAR - 07750373.pdf | U2: =IF(I2="","",DATEDIF(DATE(VALUE(RIGHT(I2,4)),VALUE(MID(I2,4,2)),VALUE(LEFT(I2,2))),TODAY(),"Y")) -> 58 | V2: =IF(U2="","",IF(U2<30,"18-29",IF(U2<40,"30-39",IF(U2<50,"40-49",IF(U2<60,"50-59","60+"))))) -> 50-59 | W2: =IF(UPPER(TRIM(J2))="PERU","PERÚ",UPPER(TRIM(J2))) -> PERÚ | X2: =UPPER(TRIM(H2)) -> FEMENINO | Y2: =UPPER(TRIM(K2)) -> AREQUIPA | Z2: =UPPER(TRIM(P2)) -> AREQUIPA
A3: AHORA NACION - AN | B3: 41618961 | C3: BUITRON MARTINEZ, FRESHMAN | D3: 41618961 | E3: BUITRON | F3: MARTINEZ | G3: FRESHMAN | H3: MASCULINO | I3: 29/09/1982 | J3: PERÚ | K3: AYACUCHO | L3: VILCAS HUAMAN | M3: VILCAS HUAMAN | N3: DIPUTADO | P3: AYACUCHO | R3: https://mpesije.jne.gob.pe/apidocs/54087930-f4c1-4c30-a5ff-c168e7cec980.jpg | S3: https://mpesije.jne.gob.pe/apidocs/a833abe4-70a4-4744-8ca4-794c861b5f05.pdf | T3: =CONCATENATE(A40," - ",B40,".pdf") -> FUERZA POPULAR - 08571708.pdf | U3: =IF(I3="","",DATEDIF(DATE(VALUE(RIGHT(I3,4)),VALUE(MID(I3,4,2)),VALUE(LEFT(I3,2))),TODAY(),"Y")) -> 43 | V3: =IF(U3="","",IF(U3<30,"18-29",IF(U3<40,"30-39",IF(U3<50,"40-49",IF(U3<60,"50-59","60+"))))) -> 40-49 | W3: =IF(UPPER(TRIM(J3))="PERU","PERÚ",UPPER(TRIM(J3))) -> PERÚ | X3: =UPPER(TRIM(H3)) -> MASCULINO | Y3: =UPPER(TRIM(K3)) -> AYACUCHO | Z3: =UPPER(TRIM(P3)) -> AYACUCHO
A4: AHORA NACION - AN | B4: 43592504 | C4: COLCHADO HUAMANI, HARVEY JULIO | D4: 43592504 | E4: COLCHADO | F4: HUAMANI | G4: HARVEY JULIO | H4: MASCULINO | I4: 11/04/1974 | J4: PERÚ | K4: LIMA | L4: LIMA | M4: LIMA | N4: DIPUTADO | P4: LIMA METROPOLITANA | R4: https://mpesije.jne.gob.pe/apidocs/aaf42d15-51c4-42da-970a-27fc9722d258.jpg | S4: https://mpesije.jne.gob.pe/apidocs/c385533c-6800-49cc-a5dd-bc890f9e6f0e.pdf | T4: =CONCATENATE(A72," - ",B72,".pdf") -> PARTIDO CIVICO OBRAS - 17930730.pdf | U4: =IF(I4="","",DATEDIF(DATE(VALUE(RIGHT(I4,4)),VALUE(MID(I4,4,2)),VALUE(LEFT(I4,2))),TODAY(),"Y")) -> 52 | V4: =IF(U4="","",IF(U4<30,"18-29",IF(U4<40,"30-39",IF(U4<50,"40-49",IF(U4<60,"50-59","60+"))))) -> 50-59 | W4: =IF(UPPER(TRIM(J4))="PERU","PERÚ",UPPER(TRIM(J4))) -> PERÚ | X4: =UPPER(TRIM(H4)) -> MASCULINO | Y4: =UPPER(TRIM(K4)) -> LIMA | Z4: =UPPER(TRIM(P4)) -> LIMA METROPOLITANA
A5: AHORA NACION - AN | B5: 43572794 | C5: HOLGUIN LOAIZA, CESAR AUGUSTO | D5: 43572794 | E5: HOLGUIN | F5: LOAIZA | G5: CESAR AUGUSTO | H5: MASCULINO | I5: 27/09/1984 | J5: PERÚ | K5: CUSCO | L5: PARURO | M5: CCAPI | N5: DIPUTADO | P5: CUSCO | R5: https://mpesije.jne.gob.pe/apidocs/20080e01-d77e-4a41-8a34-5e3a55ac4b10.jpg | S5: https://mpesije.jne.gob.pe/apidocs/27f3afef-9c95-4937-93fc-f3b66e2fbe22.pdf | T5: =CONCATENATE(A110," - ",B110,".pdf") -> - .pdf | U5: =IF(I5="","",DATEDIF(DATE(VALUE(RIGHT(I5,4)),VALUE(MID(I5,4,2)),VALUE(LEFT(I5,2))),TODAY(),"Y")) -> 41 | V5: =IF(U5="","",IF(U5<30,"18-29",IF(U5<40,"30-39",IF(U5<50,"40-49",IF(U5<60,"50-59","60+"))))) -> 40-49 | W5: =IF(UPPER(TRIM(J5))="PERU","PERÚ",UPPER(TRIM(J5))) -> PERÚ | X5: =UPPER(TRIM(H5)) -> MASCULINO | Y5: =UPPER(TRIM(K5)) -> CUSCO | Z5: =UPPER(TRIM(P5)) -> CUSCO
A6: AHORA NACION - AN | B6: 45218393 | C6: HUILCA FLORES, INDIRA ISABEL | D6: 45218393 | E6: HUILCA | F6: FLORES | G6: INDIRA ISABEL | H6: FEMENINO | I6: 11/08/1988 | J6: PERÚ | K6: LIMA | L6: LIMA | M6: LA VICTORIA | N6: DIPUTADO | P6: LIMA METROPOLITANA | R6: https://mpesije.jne.gob.pe/apidocs/00a34212-f067-4014-be90-c9a48610b7d1.jpg | S6: https://mpesije.jne.gob.pe/apidocs/df68e47e-04af-4dfe-b08d-ce5fa2659ae8.pdf | T6: =CONCATENATE(A113," - ",B113,".pdf") -> - .pdf | U6: =IF(I6="","",DATEDIF(DATE(VALUE(RIGHT(I6,4)),VALUE(MID(I6,4,2)),VALUE(LEFT(I6,2))),TODAY(),"Y")) -> 37 | V6: =IF(U6="","",IF(U6<30,"18-29",IF(U6<40,"30-39",IF(U6<50,"40-49",IF(U6<60,"50-59","60+"))))) -> 30-39 | W6: =IF(UPPER(TRIM(J6))="PERU","PERÚ",UPPER(TRIM(J6))) -> PERÚ | X6: =UPPER(TRIM(H6)) -> FEMENINO | Y6: =UPPER(TRIM(K6)) -> LIMA | Z6: =UPPER(TRIM(P6)) -> LIMA METROPOLITANA
A7: AHORA NACION - AN | B7: 70665764 | C7: MANRIQUE OLIVERA, BERNARDINO JAIR | D7: 70665764 | E7: MANRIQUE | F7: OLIVERA | G7: BERNARDINO JAIR | H7: MASCULINO | I7: 08/04/1997 | J7: PERÚ | K7: ANCASH | L7: SANTA | M7: CHIMBOTE | N7: DIPUTADO | P7: LIMA METROPOLITANA | R7: https://mpesije.jne.gob.pe/apidocs/7fadb198-1995-459d-b2bb-8111575467a4.jpg | S7: https://mpesije.jne.gob.pe/apidocs/503df6ae-606a-48e9-af8b-ec5e23e520eb.pdf | T7: =CONCATENATE(A146," - ",B146,".pdf") -> - .pdf | U7: =IF(I7="","",DATEDIF(DATE(VALUE(RIGHT(I7,4)),VALUE(MID(I7,4,2)),VALUE(LEFT(I7,2))),TODAY(),"Y")) -> 29 | V7: =IF(U7="","",IF(U7<30,"18-29",IF(U7<40,"30-39",IF(U7<50,"40-49",IF(U7<60,"50-59","60+"))))) -> 18-29 | W7: =IF(UPPER(TRIM(J7))="PERU","PERÚ",UPPER(TRIM(J7))) -> PERÚ | X7: =UPPER(TRIM(H7)) -> MASCULINO | Y7: =UPPER(TRIM(K7)) -> ANCASH | Z7: =UPPER(TRIM(P7)) -> LIMA METROPOLITANA
A8: AHORA NACION - AN | B8: 41840094 | C8: MARCELO SALAZAR, JOSE MIGUEL | D8: 41840094 | E8: MARCELO | F8: SALAZAR | G8: JOSE MIGUEL | H8: MASCULINO | I8: 02/02/1982 | J8: PERÚ | K8: LIMA | L8: LIMA | M8: SAN JUAN DE LURIGANCHO | N8: DIPUTADO | P8: ANCASH | R8: https://mpesije.jne.gob.pe/apidocs/51e57b53-4a9b-411f-b2ba-0b25bfb8aa68.jpg | S8: https://mpesije.jne.gob.pe/apidocs/b40f8d35-dab7-485d-a6af-2434b715bebe.pdf | T8: =CONCATENATE(A149," - ",B149,".pdf") -> - .pdf | U8: =IF(I8="","",DATEDIF(DATE(VALUE(RIGHT(I8,4)),VALUE(MID(I8,4,2)),VALUE(LEFT(I8,2))),TODAY(),"Y")) -> 44 | V8: =IF(U8="","",IF(U8<30,"18-29",IF(U8<40,"30-39",IF(U8<50,"40-49",IF(U8<60,"50-59","60+"))))) -> 40-49 | W8: =IF(UPPER(TRIM(J8))="PERU","PERÚ",UPPER(TRIM(J8))) -> PERÚ | X8: =UPPER(TRIM(H8)) -> MASCULINO | Y8: =UPPER(TRIM(K8)) -> LIMA | Z8: =UPPER(TRIM(P8)) -> ANCASH
A9: AHORA NACION - AN | B9: 42839004 | C9: MUEDAS BALBIESE, CESAR AUGUSTO | D9: 42839004 | E9: MUEDAS | F9: BALBIESE | G9: CESAR AUGUSTO | H9: MASCULINO | I9: 09/08/1976 | J9: PERÚ | K9: JUNIN | L9: CHUPACA | M9: CHONGOS BAJO | N9: DIPUTADO | P9: JUNIN | R9: https://mpesije.jne.gob.pe/apidocs/c0fc0177-68d3-47cf-a9f4-7a0b0edf6c9b.jpg | S9: https://mpesije.jne.gob.pe/apidocs/d9c37dcd-51fe-4c25-8a82-77241e029029.pdf | T9: =CONCATENATE(A163," - ",B163,".pdf") -> - .pdf | U9: =IF(I9="","",DATEDIF(DATE(VALUE(RIGHT(I9,4)),VALUE(MID(I9,4,2)),VALUE(LEFT(I9,2))),TODAY(),"Y")) -> 49 | V9: =IF(U9="","",IF(U9<30,"18-29",IF(U9<40,"30-39",IF(U9<50,"40-49",IF(U9<60,"50-59","60+"))))) -> 40-49 | W9: =IF(UPPER(TRIM(J9))="PERU","PERÚ",UPPER(TRIM(J9))) -> PERÚ | X9: =UPPER(TRIM(H9)) -> MASCULINO | Y9: =UPPER(TRIM(K9)) -> JUNIN | Z9: =UPPER(TRIM(P9)) -> JUNIN
A10: AHORA NACION - AN | B10: 46307918 | C10: SONCO VILLANUEVA, HELARD BLADIMIR | D10: 46307918 | E10: SONCO | F10: VILLANUEVA | G10: HELARD BLADIMIR | H10: MASCULINO | I10: 30/08/1989 | J10: PERÚ | K10: PUNO | L10: SANDIA | M10: LIMBANI | N10: DIPUTADO | P10: PUNO | R10: https://mpesije.jne.gob.pe/apidocs/51e0f0d8-3b5a-4ca2-b969-bc892642c00e.jpg | S10: https://mpesije.jne.gob.pe/apidocs/40974f5b-37d2-427d-b075-de3512eabb23.pdf | T10: =CONCATENATE(A215," - ",B215,".pdf") -> - .pdf | U10: =IF(I10="","",DATEDIF(DATE(VALUE(RIGHT(I10,4)),VALUE(MID(I10,4,2)),VALUE(LEFT(I10,2))),TODAY(),"Y")) -> 36 | V10: =IF(U10="","",IF(U10<30,"18-29",IF(U10<40,"30-39",IF(U10<50,"40-49",IF(U10<60,"50-59","60+"))))) -> 30-39 | W10: =IF(UPPER(TRIM(J10))="PERU","PERÚ",UPPER(TRIM(J10))) -> PERÚ | X10: =UPPER(TRIM(H10)) -> MASCULINO | Y10: =UPPER(TRIM(K10)) -> PUNO | Z10: =UPPER(TRIM(P10)) -> PUNO
A11: FUERZA POPULAR | B11: 09391698 | C11: ABENSUR PINASCO, JAIME AMERICO | D11: 09391698 | E11: ABENSUR | F11: PINASCO | G11: JAIME AMERICO | H11: MASCULINO | I11: 13/04/1971 | J11: PERÚ | K11: UCAYALI | L11: CORONEL PORTILLO | M11: CALLERIA | N11: DIPUTADO | P11: UCAYALI | R11: https://mpesije.jne.gob.pe/apidocs/51fc230d-44ff-4a36-81fd-cdc866d39ffb.jpg | S11: https://mpesije.jne.gob.pe/apidocs/0ffac448-7043-418f-947f-bb410ac077ca.pdf | T11: =CONCATENATE(A1485," - ",B1485,".pdf") -> - .pdf | U11: =IF(I11="","",DATEDIF(DATE(VALUE(RIGHT(I11,4)),VALUE(MID(I11,4,2)),VALUE(LEFT(I11,2))),TODAY(),"Y")) -> 55 | V11: =IF(U11="","",IF(U11<30,"18-29",IF(U11<40,"30-39",IF(U11<50,"40-49",IF(U11<60,"50-59","60+"))))) -> 50-59 | W11: =IF(UPPER(TRIM(J11))="PERU","PERÚ",UPPER(TRIM(J11))) -> PERÚ | X11: =UPPER(TRIM(H11)) -> MASCULINO | Y11: =UPPER(TRIM(K11)) -> UCAYALI | Z11: =UPPER(TRIM(P11)) -> UCAYALI
A12: FUERZA POPULAR | B12: 45382589 | C12: ALEGRIA GARCIA, LUIS ARTURO | D12: 45382589 | E12: ALEGRIA | F12: GARCIA | G12: LUIS ARTURO | H12: MASCULINO | I12: 03/08/1988 | J12: PERÚ | K12: LIMA | L12: LIMA | M12: LIMA | N12: DIPUTADO | P12: SAN MARTIN | R12: https://mpesije.jne.gob.pe/apidocs/0210df51-6f47-4b87-816a-bd7246ac72b9.jpg | S12: https://mpesije.jne.gob.pe/apidocs/450b6742-ef38-45d4-ab3e-56e72e5e2525.pdf | T12: =CONCATENATE(A1494," - ",B1494,".pdf") -> - .pdf | U12: =IF(I12="","",DATEDIF(DATE(VALUE(RIGHT(I12,4)),VALUE(MID(I12,4,2)),VALUE(LEFT(I12,2))),TODAY(),"Y")) -> 37 | V12: =IF(U12="","",IF(U12<30,"18-29",IF(U12<40,"30-39",IF(U12<50,"40-49",IF(U12<60,"50-59","60+"))))) -> 30-39 | W12: =IF(UPPER(TRIM(J12))="PERU","PERÚ",UPPER(TRIM(J12))) -> PERÚ | X12: =UPPER(TRIM(H12)) -> MASCULINO | Y12: =UPPER(TRIM(K12)) -> LIMA | Z12: =UPPER(TRIM(P12)) -> SAN MARTIN
A13: FUERZA POPULAR | B13: 15984771 | C13: ANDRADE SALGUERO DE ALVAREZ, GLADYS GRISELDA | D13: 15984771 | E13: ANDRADE | F13: SALGUERO DE ALVAREZ | G13: GLADYS GRISELDA | H13: FEMENINO | I13: 14/06/1963 | J13: PERÚ | K13: LIMA | L13: HUARAL | M13: CHANCAY | N13: DIPUTADO | P13: LIMA PROVINCIAS | R13: https://mpesije.jne.gob.pe/apidocs/2d022f8e-70ca-4f69-bb66-18caf80c35d1.jpg | S13: https://mpesije.jne.gob.pe/apidocs/be822fbb-498b-4975-8182-7486298e7a22.pdf | T13: =CONCATENATE(A1499," - ",B1499,".pdf") -> - .pdf | U13: =IF(I13="","",DATEDIF(DATE(VALUE(RIGHT(I13,4)),VALUE(MID(I13,4,2)),VALUE(LEFT(I13,2))),TODAY(),"Y")) -> 62 | V13: =IF(U13="","",IF(U13<30,"18-29",IF(U13<40,"30-39",IF(U13<50,"40-49",IF(U13<60,"50-59","60+"))))) -> 60+ | W13: =IF(UPPER(TRIM(J13))="PERU","PERÚ",UPPER(TRIM(J13))) -> PERÚ | X13: =UPPER(TRIM(H13)) -> FEMENINO | Y13: =UPPER(TRIM(K13)) -> LIMA | Z13: =UPPER(TRIM(P13)) -> LIMA PROVINCIAS
A14: FUERZA POPULAR | B14: 76030152 | C14: BARBARAN REYES, ROSANGELLA ANDREA | D14: 76030152 | E14: BARBARAN | F14: REYES | G14: ROSANGELLA ANDREA | H14: FEMENINO | I14: 24/08/1994 | J14: PERÚ | K14: LIMA | L14: LIMA | M14: LIMA | N14: DIPUTADO | P14: LIMA METROPOLITANA | R14: https://mpesije.jne.gob.pe/apidocs/fe41e940-1222-4497-b86f-66bedd7a031d.jpg | S14: https://mpesije.jne.gob.pe/apidocs/0b8d3293-4c04-49d0-9f66-36d9316df1b3.pdf | T14: =CONCATENATE(A1511," - ",B1511,".pdf") -> - .pdf | U14: =IF(I14="","",DATEDIF(DATE(VALUE(RIGHT(I14,4)),VALUE(MID(I14,4,2)),VALUE(LEFT(I14,2))),TODAY(),"Y")) -> 31 | V14: =IF(U14="","",IF(U14<30,"18-29",IF(U14<40,"30-39",IF(U14<50,"40-49",IF(U14<60,"50-59","60+"))))) -> 30-39 | W14: =IF(UPPER(TRIM(J14))="PERU","PERÚ",UPPER(TRIM(J14))) -> PERÚ | X14: =UPPER(TRIM(H14)) -> FEMENINO | Y14: =UPPER(TRIM(K14)) -> LIMA | Z14: =UPPER(TRIM(P14)) -> LIMA METROPOLITANA
A15: FUERZA POPULAR | B15: 22509175 | C15: BETETA RUBIN, KARINA JULIZA | D15: 22509175 | E15: BETETA | F15: RUBIN | G15: KARINA JULIZA | H15: FEMENINO | I15: 18/01/1975 | J15: PERÚ | K15: HUANUCO | L15: HUANUCO | M15: HUANUCO | N15: DIPUTADO | P15: HUANUCO | R15: https://mpesije.jne.gob.pe/apidocs/43176a37-cb6a-4724-be25-93f8b8855a1b.jpg | S15: https://mpesije.jne.gob.pe/apidocs/9798b7a7-1ab2-4804-ad97-510950bd4547.pdf | T15: =CONCATENATE(A1514," - ",B1514,".pdf") -> - .pdf | U15: =IF(I15="","",DATEDIF(DATE(VALUE(RIGHT(I15,4)),VALUE(MID(I15,4,2)),VALUE(LEFT(I15,2))),TODAY(),"Y")) -> 51 | V15: =IF(U15="","",IF(U15<30,"18-29",IF(U15<40,"30-39",IF(U15<50,"40-49",IF(U15<60,"50-59","60+"))))) -> 50-59 | W15: =IF(UPPER(TRIM(J15))="PERU","PERÚ",UPPER(TRIM(J15))) -> PERÚ | X15: =UPPER(TRIM(H15)) -> FEMENINO | Y15: =UPPER(TRIM(K15)) -> HUANUCO | Z15: =UPPER(TRIM(P15)) -> HUANUCO
A16: FUERZA POPULAR | B16: 40224994 | C16: BOBADILLA GALINDO, ANGEL BRUNO | D16: 40224994 | E16: BOBADILLA | F16: GALINDO | G16: ANGEL BRUNO | H16: MASCULINO | I16: 25/11/1976 | J16: PERÚ | K16: LIMA | L16: LIMA | M16: JESUS MARIA | N16: DIPUTADO | P16: CALLAO | R16: https://mpesije.jne.gob.pe/apidocs/4aa19ef9-46f1-4ff4-a11f-55fa2b686023.jpg | S16: https://mpesije.jne.gob.pe/apidocs/d48e8bb9-e8b2-4e42-8637-dab45812eff3.pdf | T16: =CONCATENATE(A1516," - ",B1516,".pdf") -> - .pdf | U16: =IF(I16="","",DATEDIF(DATE(VALUE(RIGHT(I16,4)),VALUE(MID(I16,4,2)),VALUE(LEFT(I16,2))),TODAY(),"Y")) -> 49 | V16: =IF(U16="","",IF(U16<30,"18-29",IF(U16<40,"30-39",IF(U16<50,"40-49",IF(U16<60,"50-59","60+"))))) -> 40-49 | W16: =IF(UPPER(TRIM(J16))="PERU","PERÚ",UPPER(TRIM(J16))) -> PERÚ | X16: =UPPER(TRIM(H16)) -> MASCULINO | Y16: =UPPER(TRIM(K16)) -> LIMA | Z16: =UPPER(TRIM(P16)) -> CALLAO
A17: FUERZA POPULAR | B17: 44807108 | C17: CASTILLO RIVAS, EDUARDO ENRIQUE | D17: 44807108 | E17: CASTILLO | F17: RIVAS | G17: EDUARDO ENRIQUE | H17: MASCULINO | I17: 21/10/1987 | J17: PERÚ | K17: PIURA | L17: PIURA | M17: CASTILLA | N17: DIPUTADO | P17: PIURA | R17: https://mpesije.jne.gob.pe/apidocs/d96b162f-db71-4892-ac4e-829de3492e9d.jpg | S17: https://mpesije.jne.gob.pe/apidocs/1c270718-9c38-47fc-8bf5-48b5f01ca557.pdf | T17: =CONCATENATE(A1534," - ",B1534,".pdf") -> - .pdf | U17: =IF(I17="","",DATEDIF(DATE(VALUE(RIGHT(I17,4)),VALUE(MID(I17,4,2)),VALUE(LEFT(I17,2))),TODAY(),"Y")) -> 38 | V17: =IF(U17="","",IF(U17<30,"18-29",IF(U17<40,"30-39",IF(U17<50,"40-49",IF(U17<60,"50-59","60+"))))) -> 30-39 | W17: =IF(UPPER(TRIM(J17))="PERU","PERÚ",UPPER(TRIM(J17))) -> PERÚ | X17: =UPPER(TRIM(H17)) -> MASCULINO | Y17: =UPPER(TRIM(K17)) -> PIURA | Z17: =UPPER(TRIM(P17)) -> PIURA
A18: FUERZA POPULAR | B18: 16650849 | C18: CASTRO CRUZ, JAVIER ALEJANDRO | D18: 16650849 | E18: CASTRO | F18: CRUZ | G18: JAVIER ALEJANDRO | H18: MASCULINO | I18: 09/09/1966 | J18: PERÚ | K18: LAMBAYEQUE | L18: CHICLAYO | M18: LAGUNAS | N18: DIPUTADO | P18: LAMBAYEQUE | R18: https://mpesije.jne.gob.pe/apidocs/1f66acdf-101e-4b1c-8468-4def175df0f8.jpg | S18: https://mpesije.jne.gob.pe/apidocs/dbc1874a-d204-42ce-9055-a47156e12322.pdf | T18: =CONCATENATE(A1537," - ",B1537,".pdf") -> - .pdf | U18: =IF(I18="","",DATEDIF(DATE(VALUE(RIGHT(I18,4)),VALUE(MID(I18,4,2)),VALUE(LEFT(I18,2))),TODAY(),"Y")) -> 59 | V18: =IF(U18="","",IF(U18<30,"18-29",IF(U18<40,"30-39",IF(U18<50,"40-49",IF(U18<60,"50-59","60+"))))) -> 50-59 | W18: =IF(UPPER(TRIM(J18))="PERU","PERÚ",UPPER(TRIM(J18))) -> PERÚ | X18: =UPPER(TRIM(H18)) -> MASCULINO | Y18: =UPPER(TRIM(K18)) -> LAMBAYEQUE | Z18: =UPPER(TRIM(P18)) -> LAMBAYEQUE
A19: FUERZA POPULAR | B19: 10587515 | C19: CASTRO GRANDEZ, ROYSER | D19: 10587515 | E19: CASTRO | F19: GRANDEZ | G19: ROYSER | H19: MASCULINO | I19: 07/01/1978 | J19: PERÚ | K19: AMAZONAS | L19: RODRIGUEZ DE MENDOZA | M19: SAN NICOLAS | N19: DIPUTADO | P19: AMAZONAS | R19: https://mpesije.jne.gob.pe/apidocs/15b719e1-4b47-4b44-90b3-e7e90d7c9842.jpg | S19: https://mpesije.jne.gob.pe/apidocs/ea82ddc3-c47b-4a6e-94a9-fedf8d602787.pdf | T19: =CONCATENATE(A1538," - ",B1538,".pdf") -> - .pdf | U19: =IF(I19="","",DATEDIF(DATE(VALUE(RIGHT(I19,4)),VALUE(MID(I19,4,2)),VALUE(LEFT(I19,2))),TODAY(),"Y")) -> 48 | V19: =IF(U19="","",IF(U19<30,"18-29",IF(U19<40,"30-39",IF(U19<50,"40-49",IF(U19<60,"50-59","60+"))))) -> 40-49 | W19: =IF(UPPER(TRIM(J19))="PERU","PERÚ",UPPER(TRIM(J19))) -> PERÚ | X19: =UPPER(TRIM(H19)) -> MASCULINO | Y19: =UPPER(TRIM(K19)) -> AMAZONAS | Z19: =UPPER(TRIM(P19)) -> AMAZONAS
A20: FUERZA POPULAR | B20: 07750373 | C20: CELIZ CASTILLO, RAFAEL ALDO | D20: 07750373 | E20: CELIZ | F20: CASTILLO | G20: RAFAEL ALDO | H20: MASCULINO | I20: 08/01/1969 | J20: PERÚ | K20: LIMA | L20: LIMA | M20: JESUS MARIA | N20: DIPUTADO | P20: TUMBES | R20: https://mpesije.jne.gob.pe/apidocs/48700055-eec9-404e-a7ab-37cb70abb653.jpg | S20: https://mpesije.jne.gob.pe/apidocs/cf9cf41d-cbec-433a-a05c-fe5314f2eafe.pdf | T20: =CONCATENATE(A1541," - ",B1541,".pdf") -> - .pdf | U20: =IF(I20="","",DATEDIF(DATE(VALUE(RIGHT(I20,4)),VALUE(MID(I20,4,2)),VALUE(LEFT(I20,2))),TODAY(),"Y")) -> 57 | V20: =IF(U20="","",IF(U20<30,"18-29",IF(U20<40,"30-39",IF(U20<50,"40-49",IF(U20<60,"50-59","60+"))))) -> 50-59 | W20: =IF(UPPER(TRIM(J20))="PERU","PERÚ",UPPER(TRIM(J20))) -> PERÚ | X20: =UPPER(TRIM(H20)) -> MASCULINO | Y20: =UPPER(TRIM(K20)) -> LIMA | Z20: =UPPER(TRIM(P20)) -> TUMBES
A21: FUERZA POPULAR | B21: 09536896 | C21: CHACON DE VETTORI, CECILIA ISABEL | D21: 09536896 | E21: CHACON | F21: DE VETTORI | G21: CECILIA ISABEL | H21: FEMENINO | I21: 03/02/1971 | J21: PERÚ | K21: LAMBAYEQUE | L21: CHICLAYO | M21: CHICLAYO | N21: DIPUTADO | P21: LIMA METROPOLITANA | R21: https://mpesije.jne.gob.pe/apidocs/075f4d47-7bb6-4eea-a441-5e19b60f7b47.jpg | S21: https://mpesije.jne.gob.pe/apidocs/263418a0-327e-47e2-81df-d5e4cbc93bbc.pdf | T21: =CONCATENATE(A1543," - ",B1543,".pdf") -> - .pdf | U21: =IF(I21="","",DATEDIF(DATE(VALUE(RIGHT(I21,4)),VALUE(MID(I21,4,2)),VALUE(LEFT(I21,2))),TODAY(),"Y")) -> 55 | V21: =IF(U21="","",IF(U21<30,"18-29",IF(U21<40,"30-39",IF(U21<50,"40-49",IF(U21<60,"50-59","60+"))))) -> 50-59 | W21: =IF(UPPER(TRIM(J21))="PERU","PERÚ",UPPER(TRIM(J21))) -> PERÚ | X21: =UPPER(TRIM(H21)) -> FEMENINO | Y21: =UPPER(TRIM(K21)) -> LAMBAYEQUE | Z21: =UPPER(TRIM(P21)) -> LIMA METROPOLITANA
A22: FUERZA POPULAR | B22: 40826681 | C22: COLUMBUS MURATA, DIETHELL | D22: 40826681 | E22: COLUMBUS | F22: MURATA | G22: DIETHELL | H22: MASCULINO | I22: 19/03/1981 | J22: PERÚ | K22: LIMA | L22: LIMA | M22: PUEBLO LIBRE | N22: DIPUTADO | P22: LIMA METROPOLITANA | R22: https://mpesije.jne.gob.pe/apidocs/e393717b-8477-43d8-a7a9-f3ce8f09395a.jpg | S22: https://mpesije.jne.gob.pe/apidocs/fb85f7cf-63c2-454a-b8be-caafa9482136.pdf | T22: =CONCATENATE(A1553," - ",B1553,".pdf") -> - .pdf | U22: =IF(I22="","",DATEDIF(DATE(VALUE(RIGHT(I22,4)),VALUE(MID(I22,4,2)),VALUE(LEFT(I22,2))),TODAY(),"Y")) -> 45 | V22: =IF(U22="","",IF(U22<30,"18-29",IF(U22<40,"30-39",IF(U22<50,"40-49",IF(U22<60,"50-59","60+"))))) -> 40-49 | W22: =IF(UPPER(TRIM(J22))="PERU","PERÚ",UPPER(TRIM(J22))) -> PERÚ | X22: =UPPER(TRIM(H22)) -> MASCULINO | Y22: =UPPER(TRIM(K22)) -> LIMA | Z22: =UPPER(TRIM(P22)) -> LIMA METROPOLITANA
A23: FUERZA POPULAR | B23: 42433830 | C23: DODERO JOVICH, PIERANGELI DANIELA | D23: 42433830 | E23: DODERO | F23: JOVICH | G23: PIERANGELI DANIELA | H23: FEMENINO | I23: 09/04/1984 | J23: PERÚ | K23: AREQUIPA | L23: AREQUIPA | M23: AREQUIPA | N23: DIPUTADO | P23: LIMA METROPOLITANA | R23: https://mpesije.jne.gob.pe/apidocs/38b21551-9f9d-4509-8df3-3ff196a3db73.jpg | S23: https://mpesije.jne.gob.pe/apidocs/604a338f-478d-493d-a90f-7914850bb21d.pdf | T23: =CONCATENATE(A1564," - ",B1564,".pdf") -> - .pdf | U23: =IF(I23="","",DATEDIF(DATE(VALUE(RIGHT(I23,4)),VALUE(MID(I23,4,2)),VALUE(LEFT(I23,2))),TODAY(),"Y")) -> 42 | V23: =IF(U23="","",IF(U23<30,"18-29",IF(U23<40,"30-39",IF(U23<50,"40-49",IF(U23<60,"50-59","60+"))))) -> 40-49 | W23: =IF(UPPER(TRIM(J23))="PERU","PERÚ",UPPER(TRIM(J23))) -> PERÚ | X23: =UPPER(TRIM(H23)) -> FEMENINO | Y23: =UPPER(TRIM(K23)) -> AREQUIPA | Z23: =UPPER(TRIM(P23)) -> LIMA METROPOLITANA
A24: FUERZA POPULAR | B24: 07268767 | C24: FIGARI MENDOZA, PIER PAOLO | D24: 07268767 | E24: FIGARI | F24: MENDOZA | G24: PIER PAOLO | H24: MASCULINO | I24: 14/11/1973 | J24: PERÚ | K24: LIMA | L24: LIMA | M24: MIRAFLORES | N24: DIPUTADO | P24: LIMA METROPOLITANA | R24: https://mpesije.jne.gob.pe/apidocs/ac01f508-6d64-4ea5-b2ff-42a47fe0d259.jpg | S24: https://mpesije.jne.gob.pe/apidocs/fd565fc1-e259-4d17-a0be-469e78eef6a5.pdf | T24: =CONCATENATE(A1574," - ",B1574,".pdf") -> - .pdf | U24: =IF(I24="","",DATEDIF(DATE(VALUE(RIGHT(I24,4)),VALUE(MID(I24,4,2)),VALUE(LEFT(I24,2))),TODAY(),"Y")) -> 52 | V24: =IF(U24="","",IF(U24<30,"18-29",IF(U24<40,"30-39",IF(U24<50,"40-49",IF(U24<60,"50-59","60+"))))) -> 50-59 | W24: =IF(UPPER(TRIM(J24))="PERU","PERÚ",UPPER(TRIM(J24))) -> PERÚ | X24: =UPPER(TRIM(H24)) -> MASCULINO | Y24: =UPPER(TRIM(K24)) -> LIMA | Z24: =UPPER(TRIM(P24)) -> LIMA METROPOLITANA
A25: FUERZA POPULAR | B25: 42516751 | C25: GAMARRA PITA, LUZMILA MARIA DEL CARMEN | D25: 42516751 | E25: GAMARRA | F25: PITA | G25: LUZMILA MARIA DEL CARMEN | H25: FEMENINO | I25: 02/07/1984 | J25: PERÚ | K25: LIMA | L25: LIMA | M25: JESUS MARIA | N25: DIPUTADO | P25: ANCASH | R25: https://mpesije.jne.gob.pe/apidocs/799ae78c-4935-458a-aa5c-550ceb4dadf4.jpg | S25: https://mpesije.jne.gob.pe/apidocs/b1cf36db-6a9c-423b-ae82-0a34aae7928c.pdf | T25: =CONCATENATE(A1585," - ",B1585,".pdf") -> - .pdf | U25: =IF(I25="","",DATEDIF(DATE(VALUE(RIGHT(I25,4)),VALUE(MID(I25,4,2)),VALUE(LEFT(I25,2))),TODAY(),"Y")) -> 41 | V25: =IF(U25="","",IF(U25<30,"18-29",IF(U25<40,"30-39",IF(U25<50,"40-49",IF(U25<60,"50-59","60+"))))) -> 40-49 | W25: =IF(UPPER(TRIM(J25))="PERU","PERÚ",UPPER(TRIM(J25))) -> PERÚ | X25: =UPPER(TRIM(H25)) -> FEMENINO | Y25: =UPPER(TRIM(K25)) -> LIMA | Z25: =UPPER(TRIM(P25)) -> ANCASH
A26: FUERZA POPULAR | B26: 16448130 | C26: INFANTES CASTAÑEDA, MERY ELIANA | D26: 16448130 | E26: INFANTES | F26: CASTAÑEDA | G26: MERY ELIANA | H26: FEMENINO | I26: 11/10/1963 | J26: PERÚ | K26: LAMBAYEQUE | L26: CHICLAYO | M26: NUEVA ARICA | N26: DIPUTADO | P26: AMAZONAS | R26: https://mpesije.jne.gob.pe/apidocs/1c7cad1e-55d0-4eaf-a410-3190cc45ccd9.jpg | S26: https://mpesije.jne.gob.pe/apidocs/ff1ca3f2-ec67-4f15-b8ab-a51f00002ed8.pdf | T26: =CONCATENATE(A1600," - ",B1600,".pdf") -> - .pdf | U26: =IF(I26="","",DATEDIF(DATE(VALUE(RIGHT(I26,4)),VALUE(MID(I26,4,2)),VALUE(LEFT(I26,2))),TODAY(),"Y")) -> 62 | V26: =IF(U26="","",IF(U26<30,"18-29",IF(U26<40,"30-39",IF(U26<50,"40-49",IF(U26<60,"50-59","60+"))))) -> 60+ | W26: =IF(UPPER(TRIM(J26))="PERU","PERÚ",UPPER(TRIM(J26))) -> PERÚ | X26: =UPPER(TRIM(H26)) -> FEMENINO | Y26: =UPPER(TRIM(K26)) -> LAMBAYEQUE | Z26: =UPPER(TRIM(P26)) -> AMAZONAS
A27: FUERZA POPULAR | B27: 41919665 | C27: LEIVA BAYLON, LETICIA MARUJA | D27: 41919665 | E27: LEIVA | F27: BAYLON | G27: LETICIA MARUJA | H27: FEMENINO | I27: 21/05/1983 | J27: PERÚ | K27: LIMA | L27: LIMA | M27: LIMA | N27: DIPUTADO | P27: LA LIBERTAD | R27: https://mpesije.jne.gob.pe/apidocs/b00ba9d7-66c7-480f-b8ea-b46904b30968.jpg | S27: https://mpesije.jne.gob.pe/apidocs/c8aad8f9-89d1-4e01-ad7c-eae451c94c24.pdf | T27: =CONCATENATE(A1607," - ",B1607,".pdf") -> - .pdf | U27: =IF(I27="","",DATEDIF(DATE(VALUE(RIGHT(I27,4)),VALUE(MID(I27,4,2)),VALUE(LEFT(I27,2))),TODAY(),"Y")) -> 43 | V27: =IF(U27="","",IF(U27<30,"18-29",IF(U27<40,"30-39",IF(U27<50,"40-49",IF(U27<60,"50-59","60+"))))) -> 40-49 | W27: =IF(UPPER(TRIM(J27))="PERU","PERÚ",UPPER(TRIM(J27))) -> PERÚ | X27: =UPPER(TRIM(H27)) -> FEMENINO | Y27: =UPPER(TRIM(K27)) -> LIMA | Z27: =UPPER(TRIM(P27)) -> LA LIBERTAD
A28: FUERZA POPULAR | B28: 10187011 | C28: MENDOZA BERNEDO, LIZ HULI | D28: 10187011 | E28: MENDOZA | F28: BERNEDO | G28: LIZ HULI | H28: FEMENINO | I28: 04/07/1974 | J28: PERÚ | K28: LIMA | L28: LIMA | M28: ANCON | N28: DIPUTADO | P28: PERUANOS RESIDENTES EN EL EXTRANJERO | R28: https://mpesije.jne.gob.pe/apidocs/8543846b-eaab-4b44-bda0-849122e6f396.jpg | S28: https://mpesije.jne.gob.pe/apidocs/cd39ca14-0159-40c9-843f-17264b0725ee.pdf | T28: =CONCATENATE(A1624," - ",B1624,".pdf") -> - .pdf | U28: =IF(I28="","",DATEDIF(DATE(VALUE(RIGHT(I28,4)),VALUE(MID(I28,4,2)),VALUE(LEFT(I28,2))),TODAY(),"Y")) -> 51 | V28: =IF(U28="","",IF(U28<30,"18-29",IF(U28<40,"30-39",IF(U28<50,"40-49",IF(U28<60,"50-59","60+"))))) -> 50-59 | W28: =IF(UPPER(TRIM(J28))="PERU","PERÚ",UPPER(TRIM(J28))) -> PERÚ | X28: =UPPER(TRIM(H28)) -> FEMENINO | Y28: =UPPER(TRIM(K28)) -> LIMA | Z28: =UPPER(TRIM(P28)) -> PERUANOS RESIDENTES EN EL EXTRANJERO
A29: FUERZA POPULAR | B29: 10028427 | C29: NAVAS SANCHEZ, JESSICA LIZBETH | D29: 10028427 | E29: NAVAS | F29: SANCHEZ | G29: JESSICA LIZBETH | H29: FEMENINO | I29: 09/08/1973 | J29: PERÚ | K29: UCAYALI | L29: CORONEL PORTILLO | M29: CALLERIA | N29: DIPUTADO | P29: UCAYALI | R29: https://mpesije.jne.gob.pe/apidocs/0c036c3c-b21f-4a3c-9aa0-355dc67b9d55.jpg | S29: https://mpesije.jne.gob.pe/apidocs/89f43cc1-8f03-46fa-9b73-d0610df59268.pdf | T29: =CONCATENATE(A1634," - ",B1634,".pdf") -> - .pdf | U29: =IF(I29="","",DATEDIF(DATE(VALUE(RIGHT(I29,4)),VALUE(MID(I29,4,2)),VALUE(LEFT(I29,2))),TODAY(),"Y")) -> 52 | V29: =IF(U29="","",IF(U29<30,"18-29",IF(U29<40,"30-39",IF(U29<50,"40-49",IF(U29<60,"50-59","60+"))))) -> 50-59 | W29: =IF(UPPER(TRIM(J29))="PERU","PERÚ",UPPER(TRIM(J29))) -> PERÚ | X29: =UPPER(TRIM(H29)) -> FEMENINO | Y29: =UPPER(TRIM(K29)) -> UCAYALI | Z29: =UPPER(TRIM(P29)) -> UCAYALI
A30: FUERZA POPULAR | B30: 07737110 | C30: OBANDO MORGAN, AURISTELA ANA | D30: 07737110 | E30: OBANDO | F30: MORGAN | G30: AURISTELA ANA | H30: FEMENINO | I30: 03/08/1953 | J30: PERÚ | K30: LAMBAYEQUE | L30: CHICLAYO | M30: CHICLAYO | N30: DIPUTADO | P30: CALLAO | R30: https://mpesije.jne.gob.pe/apidocs/922d4c25-0617-4447-97d6-8eaf47e4fbf2.jpg | S30: https://mpesije.jne.gob.pe/apidocs/86ed8743-9abe-4eff-9265-e83380b4c05b.pdf | T30: =CONCATENATE(A1637," - ",B1637,".pdf") -> - .pdf | U30: =IF(I30="","",DATEDIF(DATE(VALUE(RIGHT(I30,4)),VALUE(MID(I30,4,2)),VALUE(LEFT(I30,2))),TODAY(),"Y")) -> 72 | V30: =IF(U30="","",IF(U30<30,"18-29",IF(U30<40,"30-39",IF(U30<50,"40-49",IF(U30<60,"50-59","60+"))))) -> 60+ | W30: =IF(UPPER(TRIM(J30))="PERU","PERÚ",UPPER(TRIM(J30))) -> PERÚ | X30: =UPPER(TRIM(H30)) -> FEMENINO | Y30: =UPPER(TRIM(K30)) -> LAMBAYEQUE | Z30: =UPPER(TRIM(P30)) -> CALLAO
A31: FUERZA POPULAR | B31: 47000483 | C31: PACHECO QUISPE, MARCO ANTONIO | D31: 47000483 | E31: PACHECO | F31: QUISPE | G31: MARCO ANTONIO | H31: MASCULINO | I31: 14/03/1992 | J31: PERÚ | K31: LIMA | L31: LIMA | M31: VILLA EL SALVADOR | N31: DIPUTADO | P31: LIMA METROPOLITANA | R31: https://mpesije.jne.gob.pe/apidocs/eeab968c-83e6-41a2-92ec-4dfdcdb0cd7f.jpg | S31: https://mpesije.jne.gob.pe/apidocs/a561a482-3a99-43e4-9314-213f7bb4d7bf.pdf | T31: =CONCATENATE(A1646," - ",B1646,".pdf") -> - .pdf | U31: =IF(I31="","",DATEDIF(DATE(VALUE(RIGHT(I31,4)),VALUE(MID(I31,4,2)),VALUE(LEFT(I31,2))),TODAY(),"Y")) -> 34 | V31: =IF(U31="","",IF(U31<30,"18-29",IF(U31<40,"30-39",IF(U31<50,"40-49",IF(U31<60,"50-59","60+"))))) -> 30-39 | W31: =IF(UPPER(TRIM(J31))="PERU","PERÚ",UPPER(TRIM(J31))) -> PERÚ | X31: =UPPER(TRIM(H31)) -> MASCULINO | Y31: =UPPER(TRIM(K31)) -> LIMA | Z31: =UPPER(TRIM(P31)) -> LIMA METROPOLITANA
A32: FUERZA POPULAR | B32: 45721573 | C32: PALMA MENDOZA, JOSE MARVIN | D32: 45721573 | E32: PALMA | F32: MENDOZA | G32: JOSE MARVIN | H32: MASCULINO | I32: 26/05/1989 | J32: PERÚ | K32: LAMBAYEQUE | L32: CHICLAYO | M32: SANTA ROSA | N32: DIPUTADO | P32: LAMBAYEQUE | R32: https://mpesije.jne.gob.pe/apidocs/f1ccbd31-2838-4168-82d3-eb5b71f519c7.jpg | S32: https://mpesije.jne.gob.pe/apidocs/af5b875e-2cd2-4fa8-82ef-ce3f05284089.pdf | T32: =CONCATENATE(A1647," - ",B1647,".pdf") -> - .pdf | U32: =IF(I32="","",DATEDIF(DATE(VALUE(RIGHT(I32,4)),VALUE(MID(I32,4,2)),VALUE(LEFT(I32,2))),TODAY(),"Y")) -> 37 | V32: =IF(U32="","",IF(U32<30,"18-29",IF(U32<40,"30-39",IF(U32<50,"40-49",IF(U32<60,"50-59","60+"))))) -> 30-39 | W32: =IF(UPPER(TRIM(J32))="PERU","PERÚ",UPPER(TRIM(J32))) -> PERÚ | X32: =UPPER(TRIM(H32)) -> MASCULINO | Y32: =UPPER(TRIM(K32)) -> LAMBAYEQUE | Z32: =UPPER(TRIM(P32)) -> LAMBAYEQUE
A33: FUERZA POPULAR | B33: 10792277 | C33: PATIÑO URCO, ANA BERTHA | D33: 10792277 | E33: PATIÑO | F33: URCO | G33: ANA BERTHA | H33: FEMENINO | I33: 01/05/1967 | J33: PERÚ | K33: JUNIN | L33: HUANCAYO | M33: HUANCAYO | N33: DIPUTADO | P33: JUNIN | R33: https://mpesije.jne.gob.pe/apidocs/1351a920-31c9-42b8-9abc-e65fa1a12dd8.jpg | S33: https://mpesije.jne.gob.pe/apidocs/8cd2976e-3ac9-4cfd-ba3b-2ae21dbdad12.pdf | T33: =CONCATENATE(A1653," - ",B1653,".pdf") -> - .pdf | U33: =IF(I33="","",DATEDIF(DATE(VALUE(RIGHT(I33,4)),VALUE(MID(I33,4,2)),VALUE(LEFT(I33,2))),TODAY(),"Y")) -> 59 | V33: =IF(U33="","",IF(U33<30,"18-29",IF(U33<40,"30-39",IF(U33<50,"40-49",IF(U33<60,"50-59","60+"))))) -> 50-59 | W33: =IF(UPPER(TRIM(J33))="PERU","PERÚ",UPPER(TRIM(J33))) -> PERÚ | X33: =UPPER(TRIM(H33)) -> FEMENINO | Y33: =UPPER(TRIM(K33)) -> JUNIN | Z33: =UPPER(TRIM(P33)) -> JUNIN
A34: FUERZA POPULAR | B34: 41408779 | C34: PAUCARA PAXI, CARMELA | D34: 41408779 | E34: PAUCARA | F34: PAXI | G34: CARMELA | H34: FEMENINO | I34: 18/11/1979 | J34: PERÚ | K34: LIMA | L34: LIMA | M34: VILLA EL SALVADOR | N34: DIPUTADO | P34: PIURA | R34: https://mpesije.jne.gob.pe/apidocs/acf9364c-20ca-403e-bf77-0252c913b060.jpg | S34: https://mpesije.jne.gob.pe/apidocs/aaf53a26-bc0a-41c6-85ba-b6e14514bad4.pdf | T34: =CONCATENATE(A1654," - ",B1654,".pdf") -> - .pdf | U34: =IF(I34="","",DATEDIF(DATE(VALUE(RIGHT(I34,4)),VALUE(MID(I34,4,2)),VALUE(LEFT(I34,2))),TODAY(),"Y")) -> 46 | V34: =IF(U34="","",IF(U34<30,"18-29",IF(U34<40,"30-39",IF(U34<50,"40-49",IF(U34<60,"50-59","60+"))))) -> 40-49 | W34: =IF(UPPER(TRIM(J34))="PERU","PERÚ",UPPER(TRIM(J34))) -> PERÚ | X34: =UPPER(TRIM(H34)) -> FEMENINO | Y34: =UPPER(TRIM(K34)) -> LIMA | Z34: =UPPER(TRIM(P34)) -> PIURA
A35: FUERZA POPULAR | B35: 05414308 | C35: PINASCO MONTENEGRO, NARY BENVINDA | D35: 05414308 | E35: PINASCO | F35: MONTENEGRO | G35: NARY BENVINDA | H35: FEMENINO | I35: 26/10/1977 | J35: PERÚ | K35: LORETO | L35: MAYNAS | M35: IQUITOS | N35: DIPUTADO | P35: LORETO | R35: https://mpesije.jne.gob.pe/apidocs/b177f705-dfd3-4599-a882-ab395bc5346f.jpg | S35: https://mpesije.jne.gob.pe/apidocs/800f7ef6-8de6-4263-9184-22df80bdfc57.pdf | T35: =CONCATENATE(A1658," - ",B1658,".pdf") -> - .pdf | U35: =IF(I35="","",DATEDIF(DATE(VALUE(RIGHT(I35,4)),VALUE(MID(I35,4,2)),VALUE(LEFT(I35,2))),TODAY(),"Y")) -> 48 | V35: =IF(U35="","",IF(U35<30,"18-29",IF(U35<40,"30-39",IF(U35<50,"40-49",IF(U35<60,"50-59","60+"))))) -> 40-49 | W35: =IF(UPPER(TRIM(J35))="PERU","PERÚ",UPPER(TRIM(J35))) -> PERÚ | X35: =UPPER(TRIM(H35)) -> FEMENINO | Y35: =UPPER(TRIM(K35)) -> LORETO | Z35: =UPPER(TRIM(P35)) -> LORETO
A36: FUERZA POPULAR | B36: 44275599 | C36: REVILLA VILLANUEVA, CESAR MANUEL | D36: 44275599 | E36: REVILLA | F36: VILLANUEVA | G36: CESAR MANUEL | H36: MASCULINO | I36: 19/03/1987 | J36: PERÚ | K36: LAMBAYEQUE | L36: CHICLAYO | M36: CHICLAYO | N36: DIPUTADO | P36: PIURA | R36: https://mpesije.jne.gob.pe/apidocs/c239bb01-32d8-47ae-ac26-e62459fe1f18.jpg | S36: https://mpesije.jne.gob.pe/apidocs/994926dc-049b-4590-b5cf-8e1251762deb.pdf | T36: =CONCATENATE(A1671," - ",B1671,".pdf") -> - .pdf | U36: =IF(I36="","",DATEDIF(DATE(VALUE(RIGHT(I36,4)),VALUE(MID(I36,4,2)),VALUE(LEFT(I36,2))),TODAY(),"Y")) -> 39 | V36: =IF(U36="","",IF(U36<30,"18-29",IF(U36<40,"30-39",IF(U36<50,"40-49",IF(U36<60,"50-59","60+"))))) -> 30-39 | W36: =IF(UPPER(TRIM(J36))="PERU","PERÚ",UPPER(TRIM(J36))) -> PERÚ | X36: =UPPER(TRIM(H36)) -> MASCULINO | Y36: =UPPER(TRIM(K36)) -> LAMBAYEQUE | Z36: =UPPER(TRIM(P36)) -> PIURA
A37: FUERZA POPULAR | B37: 80328889 | C37: SALAS RIVERA, ALEXANDER | D37: 80328889 | E37: SALAS | F37: RIVERA | G37: ALEXANDER | H37: MASCULINO | I37: 14/05/1979 | J37: PERÚ | K37: LIMA | L37: CAÑETE | M37: SAN VICENTE DE CAÑETE | N37: DIPUTADO | P37: LIMA PROVINCIAS | R37: https://mpesije.jne.gob.pe/apidocs/2595a793-7375-4430-91d4-9cbc362c884d.jpg | S37: https://mpesije.jne.gob.pe/apidocs/7cf2d539-5f52-4560-8ea2-174a66ade6fe.pdf | T37: =CONCATENATE(A1687," - ",B1687,".pdf") -> - .pdf | U37: =IF(I37="","",DATEDIF(DATE(VALUE(RIGHT(I37,4)),VALUE(MID(I37,4,2)),VALUE(LEFT(I37,2))),TODAY(),"Y")) -> 47 | V37: =IF(U37="","",IF(U37<30,"18-29",IF(U37<40,"30-39",IF(U37<50,"40-49",IF(U37<60,"50-59","60+"))))) -> 40-49 | W37: =IF(UPPER(TRIM(J37))="PERU","PERÚ",UPPER(TRIM(J37))) -> PERÚ | X37: =UPPER(TRIM(H37)) -> MASCULINO | Y37: =UPPER(TRIM(K37)) -> LIMA | Z37: =UPPER(TRIM(P37)) -> LIMA PROVINCIAS
A38: FUERZA POPULAR | B38: 27424381 | C38: TICLLA RAFAEL, SEGUNDO SENOVIO | D38: 27424381 | E38: TICLLA | F38: RAFAEL | G38: SEGUNDO SENOVIO | H38: MASCULINO | I38: 05/09/1973 | J38: PERÚ | K38: CAJAMARCA | L38: CHOTA | M38: CHOTA | N38: DIPUTADO | P38: CAJAMARCA | R38: https://mpesije.jne.gob.pe/apidocs/ea749409-747d-429b-a6ea-fabdb2095247.jpg | S38: https://mpesije.jne.gob.pe/apidocs/afc7375e-ec92-484d-91f2-8092fb1da4af.pdf | T38: =CONCATENATE(A1705," - ",B1705,".pdf") -> - .pdf | U38: =IF(I38="","",DATEDIF(DATE(VALUE(RIGHT(I38,4)),VALUE(MID(I38,4,2)),VALUE(LEFT(I38,2))),TODAY(),"Y")) -> 52 | V38: =IF(U38="","",IF(U38<30,"18-29",IF(U38<40,"30-39",IF(U38<50,"40-49",IF(U38<60,"50-59","60+"))))) -> 50-59 | W38: =IF(UPPER(TRIM(J38))="PERU","PERÚ",UPPER(TRIM(J38))) -> PERÚ | X38: =UPPER(TRIM(H38)) -> MASCULINO | Y38: =UPPER(TRIM(K38)) -> CAJAMARCA | Z38: =UPPER(TRIM(P38)) -> CAJAMARCA
A39: FUERZA POPULAR | B39: 40433187 | C39: TORRES MORALES, MIGUEL ANGEL | D39: 40433187 | E39: TORRES | F39: MORALES | G39: MIGUEL ANGEL | H39: MASCULINO | I39: 18/02/1980 | J39: PERÚ | K39: LIMA | L39: LIMA | M39: LINCE | N39: SEGUNDO VICEPRESIDENTE DE LA REPÚBLICA | O39: SENADOR | P39: ÚNICO NACIONAL | R39: https://mpesije.jne.gob.pe/apidocs/789b7714-8633-4a59-a89b-7fab4646fef1.jpeg | S39: https://mpesije.jne.gob.pe/apidocs/99872797-b3bf-452e-939b-06d1cdeaa917.pdf | T39: =CONCATENATE(A1709," - ",B1709,".pdf") -> - .pdf | U39: =IF(I39="","",DATEDIF(DATE(VALUE(RIGHT(I39,4)),VALUE(MID(I39,4,2)),VALUE(LEFT(I39,2))),TODAY(),"Y")) -> 46 | V39: =IF(U39="","",IF(U39<30,"18-29",IF(U39<40,"30-39",IF(U39<50,"40-49",IF(U39<60,"50-59","60+"))))) -> 40-49 | W39: =IF(UPPER(TRIM(J39))="PERU","PERÚ",UPPER(TRIM(J39))) -> PERÚ | X39: =UPPER(TRIM(H39)) -> MASCULINO | Y39: =UPPER(TRIM(K39)) -> LIMA | Z39: =UPPER(TRIM(P39)) -> ÚNICO NACIONAL
A40: FUERZA POPULAR | B40: 08571708 | C40: TRUJILLO ZEGARRA, GILMER | D40: 08571708 | E40: TRUJILLO | F40: ZEGARRA | G40: GILMER | H40: MASCULINO | I40: 20/06/1966 | J40: PERÚ | K40: LIMA | L40: LIMA | M40: LIMA | N40: DIPUTADO | P40: LA LIBERTAD | R40: https://mpesije.jne.gob.pe/apidocs/4a6db76e-4a02-49f7-8d84-0ad1b851903f.jpg | S40: https://mpesije.jne.gob.pe/apidocs/2520e18a-e627-445c-a066-b83aadc43341.pdf | T40: =CONCATENATE(A1710," - ",B1710,".pdf") -> - .pdf | U40: =IF(I40="","",DATEDIF(DATE(VALUE(RIGHT(I40,4)),VALUE(MID(I40,4,2)),VALUE(LEFT(I40,2))),TODAY(),"Y")) -> 59 | V40: =IF(U40="","",IF(U40<30,"18-29",IF(U40<40,"30-39",IF(U40<50,"40-49",IF(U40<60,"50-59","60+"))))) -> 50-59 | W40: =IF(UPPER(TRIM(J40))="PERU","PERÚ",UPPER(TRIM(J40))) -> PERÚ | X40: =UPPER(TRIM(H40)) -> MASCULINO | Y40: =UPPER(TRIM(K40)) -> LIMA | Z40: =UPPER(TRIM(P40)) -> LA LIBERTAD
...

Sheet RESUMEN_DP
A1: Total candidatos | B1: Mujeres | C1: Hombres | D1: Edad promedio | E1: Edad mediana | F1: Edad mínima | G1: Edad máxima
A2: =COUNTA('01 DATOS PERSONALES'!B2:B1000) -> 100 | B2: =COUNTIF('01 DATOS PERSONALES'!X2:Y1000,"FEMENINO") -> 39 | C2: =COUNTIF('01 DATOS PERSONALES'!X2:Y1000,"MASCULINO") -> 61 | D2: =AVERAGE('01 DATOS PERSONALES'!U2:U1000) -> 49.18 | E2: =MEDIAN('01 DATOS PERSONALES'!U2:U1000) -> 48 | F2: =MIN('01 DATOS PERSONALES'!U2:U1000) -> 29 | G2: =MAX('01 DATOS PERSONALES'!U2:U1000) -> 77

Sheet PIVOT_DP_ORG
F1: PARIDAD
F2: % mujeres | G2: % hombres
F3: =B3/D3 -> 0.22222222 | G3: =C3/D3 -> 0.77777778
F4: =B4/D4 -> 0.42424242 | G4: =C4/D4 -> 0.57575758
F5: =B5/D5 -> 0.47058824 | G5: =C5/D5 -> 0.52941176
F6: =B6/D6 -> 0.23076923 | G6: =C6/D6 -> 0.76923077
F7: =B7/D7 -> 0.57142857 | G7: =C7/D7 -> 0.42857143
F8: =B8/D8 -> 0.28571429 | G8: =C8/D8 -> 0.71428571

Sheet 02 EXPERIENCIA LABORAL
A1: ORGANIZACION_POLITICA | B1: DNI_CANDIDATO | C1: CANDIDATO | D1: TIENE_EXPERIENCIA_LABORAL | E1: CENTRO_TRABAJO | F1: PROFESION_OCUPACION | G1: RUC | H1: DIRECCION | I1: AÑO_DESDE | J1: AÑO_HASTA | K1: PAIS | L1: DEPARTAMENTO | M1: PROVINCIA | N1: DISTRITO | O1: INFORMACION_ADICIONAL | P1: TRABAJO_CONGRESO
A2: AHORA NACION - AN | B2: 29569533 | C2: ARMINTA VALENCIA, MARLENY BIBIANA | D2: SI | E2: Inversiones Plus EIRL | F2: Asesora Gerencial Externa | G2: 20498689877 | H2: MZA. F LOTE. 13 DPTO. 102 URB. LA ESPERANZA (COSTADO COLEGIO ESTELA MARIS) AREQUIPA - AREQUIPA - JOS | I2: 2018 | J2: 2022 | K2: PERU | L2: AREQUIPA | M2: AREQUIPA | N2: JOSE LUIS BUSTAMANTE Y RIVERO | P2: =IFERROR(__xludf.DUMMYFUNCTION("IF(REGEXMATCH(UPPER(E2),""CONGRESO""),1,0)"),0.0) -> 0
A3: AHORA NACION - AN | B3: 29569533 | C3: ARMINTA VALENCIA, MARLENY BIBIANA | D3: SI | E3: Gobierno Regional de Arequipa | F3: Consejera Regional de Arequipa | G3: 20498390570 | H3: Calle Bolívar N° 206 Cercado | I3: 2023 | J3: 2025 | K3: PERU | L3: AREQUIPA | M3: AREQUIPA | N3: AREQUIPA | P3: =IFERROR(__xludf.DUMMYFUNCTION("IF(REGEXMATCH(UPPER(E3),""CONGRESO""),1,0)"),0.0) -> 0
A4: AHORA NACION - AN | B4: 41618961 | C4: BUITRON MARTINEZ, FRESHMAN | D4: SI | E4: Servicios Falcons EIRL | F4: Gerente | G4: 20602115349 | H4: Av. Ramón Castilla N° 406 | I4: 2018 | J4: 2025 | K4: PERU | L4: AYACUCHO | M4: HUAMANGA | N4: SAN JUAN BAUTISTA | O4: Sigo laborando y registrado en la planilla de la institución hasta la actualidad en Servicios Falcons EIRL | P4: =IFERROR(__xludf.DUMMYFUNCTION("IF(REGEXMATCH(UPPER(E4),""CONGRESO""),1,0)"),0.0) -> 0
A5: AHORA NACION - AN | B5: 43592504 | C5: COLCHADO HUAMANI, HARVEY JULIO | D5: SI | E5: División de Investigaciones de Alta Complejidad (DIVIAC) | F5: Jefe de División | H5: Av. Pedro Venturo Nro 403 - Urb Higuereta | I5: 2023 | J5: 2024 | K5: PERU | L5: LIMA | M5: LIMA | N5: SANTIAGO DE SURCO | O5: Cargo desempeñado desde el 31 Oct 2023 hasta el 13 Abr 2024, dependiente de la DIRNIC PNP | P5: =IFERROR(__xludf.DUMMYFUNCTION("IF(REGEXMATCH(UPPER(E5),""CONGRESO""),1,0)"),0.0) -> 0
A6: AHORA NACION - AN | B6: 43592504 | C6: COLCHADO HUAMANI, HARVEY JULIO | D6: SI | E6: II MACREPOL Lambayeque | F6: Jefe de la Región Policial Lambayeque | H6: Av. José Balta - Complejo Policial 07 de Agosto | I6: 2021 | J6: 2022 | K6: PERU | L6: LAMBAYEQUE | M6: CHICLAYO | N6: CHICLAYO | O6: Mayo 2021 a Feb 2022 | P6: =IFERROR(__xludf.DUMMYFUNCTION("IF(REGEXMATCH(UPPER(E6),""CONGRESO""),1,0)"),0.0) -> 0
A7: AHORA NACION - AN | B7: 43592504 | C7: COLCHADO HUAMANI, HARVEY JULIO | D7: SI | E7: Dirección de Medioambiente - PNP | F7: Jefe de Secretaría | H7: Calle Rivero de Ustaris 251 | I7: 2022 | J7: 2022 | K7: PERU | L7: LIMA | M7: LIMA | N7: JESUS MARIA | O7: Cargo desempeñado desde febrero del 2022 a Julio del 2022, primero como Jefe de la División contra la Tala Ilegal y Protección de Recursos Naturales de la DIRMEAMB | P7: =IFERROR(__xludf.DUMMYFUNCTION("IF(REGEXMATCH(UPPER(E7),""CONGRESO""),1,0)"),0.0) -> 0
A8: AHORA NACION - AN | B8: 43592504 | C8: COLCHADO HUAMANI, HARVEY JULIO | D8: SI | E8: Observatorio del Delito y la Criminalidad - DIRNIC PNP | F8: Jefe de Unidad | H8: Plaza 30 de Agosto S/N, Urb. Corpac - MININTER | I8: 2024 | J8: 2024 | K8: PERU | L8: LIMA | M8: LIMA | N8: SAN ISIDRO | O8: Prestó servicios del 15 Abr al 31 Dic 2024 | P8: =IFERROR(__xludf.DUMMYFUNCTION("IF(REGEXMATCH(UPPER(E8),""CONGRESO""),1,0)"),0.0) -> 0
A9: AHORA NACION - AN | B9: 43592504 | C9: COLCHADO HUAMANI, HARVEY JULIO | D9: SI | E9: Dirección General de Inteligencia - MININTER | F9: Jefe de División de Búsqueda | H9: Casa de Seguridad (dir. reservada) | I9: 2022 | J9: 2023 | K9: PERU | L9: LIMA | M9: LIMA | N9: LIMA | O9: Con RM Nro. 903-2022 del 18JUL2022, fue designado como coordinador general del Equipo Especial de Apoyo al Equipo Especial de Fiscales Contra la Corrupción en el Poder - EFICCOP. | P9: =IFERROR(__xludf.DUMMYFUNCTION("IF(REGEXMATCH(UPPER(E9),""CONGRESO""),1,0)"),0.0) -> 0
A10: AHORA NACION - AN | B10: 43572794 | C10: HOLGUIN LOAIZA, CESAR AUGUSTO | D10: SI | E10: Universidad Andina del Cusco | F10: Docente | G10: 20177395227 | H10: Urb. Ingeniería Larapa Grande A-7, San Jerónimo | I10: 2023 | J10: 2024 | K10: PERU | L10: CUSCO | M10: CUSCO | N10: SAN JERONIMO | O10: Docente en la escuela profesional de economía | P10: =IFERROR(__xludf.DUMMYFUNCTION("IF(REGEXMATCH(UPPER(E10),""CONGRESO""),1,0)"),0.0) -> 0
A11: AHORA NACION - AN | B11: 43572794 | C11: HOLGUIN LOAIZA, CESAR AUGUSTO | D11: SI | E11: Ministerio de Economía y Finanzas | F11: Consultor / Inversión privada | G11: 20131370645 | H11: Jr. Lampa 594 | I11: 2021 | J11: 2022 | K11: PERU | L11: LIMA | M11: LIMA | N11: LIMA | O11: Temas: Políticas de Promoción de la Inversión Privada. | P11: =IFERROR(__xludf.DUMMYFUNCTION("IF(REGEXMATCH(UPPER(E11),""CONGRESO""),1,0)"),0.0) -> 0
A12: AHORA NACION - AN | B12: 43572794 | C12: HOLGUIN LOAIZA, CESAR AUGUSTO | D12: SI | E12: Consultoría Independiente | F12: Consultor / Inversión privada | H12: Av Grau 4-5 Apu Zarzuela Baja | I12: 2021 | J12: 2022 | K12: PERU | L12: CUSCO | M12: CUSCO | N12: CUSCO | O12: En los municipios distritales de OMACHA, CHALLABAMBA y VILLCABAMBA | P12: =IFERROR(__xludf.DUMMYFUNCTION("IF(REGEXMATCH(UPPER(E12),""CONGRESO""),1,0)"),0.0) -> 0
A13: AHORA NACION - AN | B13: 43572794 | C13: HOLGUIN LOAIZA, CESAR AUGUSTO | D13: SI | E13: Apu Millenium SAC | F13: Docente | G13: 20602298214 | H13: Av. La Cultura N° 1008 | I13: 2019 | J13: 2025 | K13: PERU | L13: CUSCO | M13: PARURO | N13: OMACHA | O13: Elaboración de material educativo. | P13: =IFERROR(__xludf.DUMMYFUNCTION("IF(REGEXMATCH(UPPER(E13),""CONGRESO""),1,0)"),0.0) -> 0
A14: AHORA NACION - AN | B14: 43572794 | C14: HOLGUIN LOAIZA, CESAR AUGUSTO | D14: SI | E14: Municipalidad Distrital de San Sebastián | F14: Consultor - Gestión Pública | G14: 20159308961 | H14: Plaza de Armas San Sebastián S/N | I14: 2023 | J14: 2023 | K14: PERU | L14: CUSCO | M14: CUSCO | N14: SAN SEBASTIAN | O14: Especialista en Gobernanza e infraestructura | P14: =IFERROR(__xludf.DUMMYFUNCTION("IF(REGEXMATCH(UPPER(E14),""CONGRESO""),1,0)"),0.0) -> 0
A15: AHORA NACION - AN | B15: 45218393 | C15: HUILCA FLORES, INDIRA ISABEL | D15: SI | E15: Asociación Pro Derechos Humanos | F15: Socióloga | H15: Calle Pachacutec 980 | I15: 2024 | J15: 2025 | K15: PERU | L15: LIMA | M15: LIMA | N15: JESUS MARIA | P15: =IFERROR(__xludf.DUMMYFUNCTION("IF(REGEXMATCH(UPPER(E15),""CONGRESO""),1,0)"),0.0) -> 0
A16: AHORA NACION - AN | B16: 45218393 | C16: HUILCA FLORES, INDIRA ISABEL | D16: SI | E16: Centro de la Mujer Peruana Flora Tristán | F16: Consultora Socióloga | H16: Parque Hernán Velarde N° 42 Lima | I16: 2025 | J16: 2025 | K16: PERU | L16: LIMA | M16: LIMA | N16: LIMA | P16: =IFERROR(__xludf.DUMMYFUNCTION("IF(REGEXMATCH(UPPER(E16),""CONGRESO""),1,0)"),0.0) -> 0
A17: AHORA NACION - AN | B17: 45218393 | C17: HUILCA FLORES, INDIRA ISABEL | D17: SI | E17: Servicios Educativos El Agustino SEA | F17: Sociologa | H17: Jr Renan Elias Olivera 249 | I17: 2025 | J17: 2025 | K17: PERU | L17: LIMA | M17: LIMA | N17: EL AGUSTINO | P17: =IFERROR(__xludf.DUMMYFUNCTION("IF(REGEXMATCH(UPPER(E17),""CONGRESO""),1,0)"),0.0) -> 0
A18: AHORA NACION - AN | B18: 45218393 | C18: HUILCA FLORES, INDIRA ISABEL | D18: SI | E18: Centro de Estudios y Promoción del Desarrollo Ciudadano - DESCO Ciudadano | F18: Consultora Sociologa | H18: Mz G Lt 10 Sector 2, Grupo 5, Villa el Salvador | I18: 2025 | J18: 2025 | K18: PERU | L18: LIMA | M18: LIMA | N18: VILLA EL SALVADOR | P18: =IFERROR(__xludf.DUMMYFUNCTION("IF(REGEXMATCH(UPPER(E18),""CONGRESO""),1,0)"),0.0) -> 0
A19: AHORA NACION - AN | B19: 45218393 | C19: HUILCA FLORES, INDIRA ISABEL | D19: SI | E19: Fundación Friedrich Egert | F19: Sociologa | H19: Av Camino Real No 492 | I19: 2025 | J19: 2025 | K19: PERU | L19: LIMA | M19: LIMA | N19: SAN ISIDRO | P19: =IFERROR(__xludf.DUMMYFUNCTION("IF(REGEXMATCH(UPPER(E19),""CONGRESO""),1,0)"),0.0) -> 0
A20: AHORA NACION - AN | B20: 70665764 | C20: MANRIQUE OLIVERA, BERNARDINO JAIR | D20: SI | E20: Tectopia Perú | F20: AI Developer | H20: Calle Berlin 438 | I20: 2023 | J20: 2025 | K20: PERU | L20: LIMA | M20: LIMA | N20: MIRAFLORES | P20: =IFERROR(__xludf.DUMMYFUNCTION("IF(REGEXMATCH(UPPER(E20),""CONGRESO""),1,0)"),0.0) -> 0
A21: AHORA NACION - AN | B21: 70665764 | C21: MANRIQUE OLIVERA, BERNARDINO JAIR | D21: SI | E21: Divelia SAC | F21: CEO & Digital Transformator | G21: 20607140686 | H21: Calle Berlin 438 | I21: 2020 | J21: 2024 | K21: PERU | L21: LIMA | M21: LIMA | N21: MIRAFLORES | P21: =IFERROR(__xludf.DUMMYFUNCTION("IF(REGEXMATCH(UPPER(E21),""CONGRESO""),1,0)"),0.0) -> 0
A22: AHORA NACION - AN | B22: 70665764 | C22: MANRIQUE OLIVERA, BERNARDINO JAIR | D22: SI | E22: INICTEL UNI | F22: Docente Blockchain | G22: 20514761826 | H22: Av San Luis 1771 | I22: 2023 | J22: 2023 | K22: PERU | L22: LIMA | M22: LIMA | N22: SAN BORJA | O22: Servicios por honorarios | P22: =IFERROR(__xludf.DUMMYFUNCTION("IF(REGEXMATCH(UPPER(E22),""CONGRESO""),1,0)"),0.0) -> 0
A23: AHORA NACION - AN | B23: 70665764 | C23: MANRIQUE OLIVERA, BERNARDINO JAIR | D23: SI | E23: Marina de Guerra del Perú | F23: Programador de Parámetros Meteorológicos | G23: 20153408191 | H23: Calle Roca 118 | I23: 2025 | J23: 2025 | K23: PERU | L23: CALLAO | M23: CALLAO | N23: CALLAO | O23: Prestación de servicios | P23: =IFERROR(__xludf.DUMMYFUNCTION("IF(REGEXMATCH(UPPER(E23),""CONGRESO""),1,0)"),0.0) -> 0
A24: AHORA NACION - AN | B24: 70665764 | C24: MANRIQUE OLIVERA, BERNARDINO JAIR | D24: SI | E24: Fdex Asesores SAC | F24: CEO & Full Stack Developer | G24: 20603216700 | H24: Blvd. Plaza Mantaro 102 | I24: 2018 | J24: 2020 | K24: PERU | L24: LIMA | M24: LIMA | N24: SAN MIGUEL | P24: =IFERROR(__xludf.DUMMYFUNCTION("IF(REGEXMATCH(UPPER(E24),""CONGRESO""),1,0)"),0.0) -> 0
A25: AHORA NACION - AN | B25: 41840094 | C25: MARCELO SALAZAR, JOSE MIGUEL | D25: SI | E25: Banco BBVA | F25: Gerente de Oficina | G25: 20100130204 | H25: Av. Republica de Panamá 3055 | I25: 2016 | J25: 2019 | K25: PERU | L25: LIMA | M25: LIMA | N25: SAN ISIDRO | P25: =IFERROR(__xludf.DUMMYFUNCTION("IF(REGEXMATCH(UPPER(E25),""CONGRESO""),1,0)"),0.0) -> 0
A26: AHORA NACION - AN | B26: 41840094 | C26: MARCELO SALAZAR, JOSE MIGUEL | D26: SI | E26: Autoridad de Transporte Urbano (ATU) | F26: Especialista económico Financiero | G26: 20604932964 | H26: Calle Jose Galvez N° 550 | I26: 2024 | J26: 2025 | K26: PERU | L26: LIMA | M26: LIMA | N26: MIRAFLORES | O26: Locador | P26: =IFERROR(__xludf.DUMMYFUNCTION("IF(REGEXMATCH(UPPER(E26),""CONGRESO""),1,0)"),0.0) -> 0
A27: AHORA NACION - AN | B27: 41840094 | C27: MARCELO SALAZAR, JOSE MIGUEL | D27: SI | E27: Municipalidad Metropolitana de Lima | F27: Especialista Económico Financiero | G27: 20131380951 | H27: Rufino Torrico 1778- Cercado de Lima | I27: 2025 | J27: 2025 | K27: PERU | L27: LIMA | M27: LIMA | N27: LIMA | O27: Locador. | P27: =IFERROR(__xludf.DUMMYFUNCTION("IF(REGEXMATCH(UPPER(E27),""CONGRESO""),1,0)"),0.0) -> 0
A28: AHORA NACION - AN | B28: 41840094 | C28: MARCELO SALAZAR, JOSE MIGUEL | D28: SI | E28: Municipalidad Distrital De San Marcos | F28: Gerente de Administración | G28: 20166544000 | H28: jiron progreso n° 332 | I28: 2021 | J28: 2022 | K28: PERU | L28: ANCASH | M28: HUARI | N28: SAN MARCOS | P28: =IFERROR(__xludf.DUMMYFUNCTION("IF(REGEXMATCH(UPPER(E28),""CONGRESO""),1,0)"),0.0) -> 0
A29: AHORA NACION - AN | B29: 42839004 | C29: MUEDAS BALBIESE, CESAR AUGUSTO | D29: SI | E29: Centro de Conciliación "Conciliación del Centro" | F29: Conciliador | H29: Jr. Julio C. Tello N° 766 | I29: 2024 | J29: 2025 | K29: PERU | L29: JUNIN | M29: HUANCAYO | N29: EL TAMBO | O29: Director y conciliador con especialización en familia. | P29: =IFERROR(__xludf.DUMMYFUNCTION("IF(REGEXMATCH(UPPER(E29),""CONGRESO""),1,0)"),0.0) -> 0
A30: AHORA NACION - AN | B30: 42839004 | C30: MUEDAS BALBIESE, CESAR AUGUSTO | D30: SI | E30: Inmobiliaria y Constructora Techo Seguro Perú EIRL | F30: Gerente - Titular | G30: 20610120301 | H30: Jr. Julio C. Tello 766 | I30: 2022 | J30: 2025 | K30: PERU | L30: JUNIN | M30: HUANCAYO | N30: EL TAMBO | P30: =IFERROR(__xludf.DUMMYFUNCTION("IF(REGEXMATCH(UPPER(E30),""CONGRESO""),1,0)"),0.0) -> 0
A31: AHORA NACION - AN | B31: 42839004 | C31: MUEDAS BALBIESE, CESAR AUGUSTO | D31: SI | E31: Radiodifusora Huancayo SAC | F31: Director - conductor | G31: 20112257994 | H31: Calle Real N° 577 Of. 403 | I31: 1998 | J31: 2025 | K31: PERU | L31: JUNIN | M31: HUANCAYO | N31: HUANCAYO | O31: Director y conductor del programa informativo Huancayo Noticias. | P31: =IFERROR(__xludf.DUMMYFUNCTION("IF(REGEXMATCH(UPPER(E31),""CONGRESO""),1,0)"),0.0) -> 0
A32: AHORA NACION - AN | B32: 42839004 | C32: MUEDAS BALBIESE, CESAR AUGUSTO | D32: SI | E32: Instituto de Investigación Peruana de Política Social y Derecho Constitucional | F32: Presidente- Fundador | G32: 20610233008 | H32: Jr. Julio C. Tello N° 766 | I32: 2022 | J32: 2025 | K32: PERU | L32: JUNIN | M32: HUANCAYO | N32: EL TAMBO | P32: =IFERROR(__xludf.DUMMYFUNCTION("IF(REGEXMATCH(UPPER(E32),""CONGRESO""),1,0)"),0.0) -> 0
A33: AHORA NACION - AN | B33: 46307918 | C33: SONCO VILLANUEVA, HELARD BLADIMIR | D33: SI | E33: Trabajador independiente | F33: Comerciante | H33: Interior del mercado Pedro Vilcapoza | I33: 2014 | J33: 2025 | K33: PERU | L33: PUNO | M33: SAN ROMAN | N33: JULIACA | O33: Puesto de venta N° 35 pabellón 3 de la sección carnes. | P33: =IFERROR(__xludf.DUMMYFUNCTION("IF(REGEXMATCH(UPPER(E33),""CONGRESO""),1,0)"),0.0) -> 0
A34: FUERZA POPULAR | B34: 09391698 | C34: ABENSUR PINASCO, JAIME AMERICO | D34: SI | E34: CONGRESO DE LA REPUBLICA | F34: ESPECIALISTA PARLAMENTARIO | G34: 20161749126 | H34: PLAZA BOLIVAR - AV. ABANCAY S/N | I34: 2004 | J34: 2025 | K34: PERU | L34: LIMA | M34: LIMA | N34: LIMA | O34: * DESDE 2004 HASTA 19-06-2025 *DIRECTOR GENERAL PARLAMENTARIO DEL CONGRESO DE LA REPÚBLICA ( 2023 - 2025) | P34: =IFERROR(__xludf.DUMMYFUNCTION("IF(REGEXMATCH(UPPER(E34),""CONGRESO""),1,0)"),1.0) -> 1
A35: FUERZA POPULAR | B35: 09391698 | C35: ABENSUR PINASCO, JAIME AMERICO | D35: SI | E35: CONGRESO DE LA REPUBLICA | F35: ASESOR PARLAMENTARIO | G35: 20161749126 | H35: PLAZA BOLÍVAR - AV.ABANCAY S/N | I35: 2025 | J35: 2025 | K35: PERU | L35: LIMA | M35: LIMA | N35: LIMA | O35: *DESDE 20-06-2025 HASTA LA ACTUALIDAD *ACTUALMENTE DIRECTOR GENERAL PARLAMENTARIO DEL CONGRESO DE LA REPUBLICA | P35: =IFERROR(__xludf.DUMMYFUNCTION("IF(REGEXMATCH(UPPER(E35),""CONGRESO""),1,0)"),1.0) -> 1
A36: FUERZA POPULAR | B36: 45382589 | C36: ALEGRIA GARCIA, LUIS ARTURO | D36: SI | E36: CONGRESO DE LA REPÚBLICA | F36: ASISTENTE NIVEL SA-2 EN EL DESPACHO DEL EX CONGRESISTA LUIS GALARRETA | G36: 20161749126 | H36: Jr. Azángaro 468 | I36: 2011 | J36: 2013 | K36: PERU | L36: LIMA | M36: LIMA | N36: LIMA | O36: desde el 28 de julio de 2011 hasta el 12 de agosto de 2013 en el cargo de Asistente Nivel SA-2 en el despacho del ex Congresista Luis Galarreta | P36: =IFERROR(__xludf.DUMMYFUNCTION("IF(REGEXMATCH(UPPER(E36),""CONGRESO""),1,0)"),1.0) -> 1
A37: FUERZA POPULAR | B37: 45382589 | C37: ALEGRIA GARCIA, LUIS ARTURO | D37: SI | E37: CONGRESO DE LA REPÚBLICA | F37: ASISTENTE NIVEL SA-2 EN EL DESPACHO DEL EX CONGRESISTA LUIS GALARRETA | G37: 20161749126 | H37: Jr. Azángaro 468 | I37: 2009 | J37: 2011 | K37: PERU | L37: LIMA | M37: LIMA | N37: LIMA | O37: desde el 3 de agosto de 2009 hasta el 26 de julio de 2011, en el cargo de asistente nivel SA-2, en el Despacho del ex Congresista Luis Fernando Galarreta Velarde. | P37: =IFERROR(__xludf.DUMMYFUNCTION("IF(REGEXMATCH(UPPER(E37),""CONGRESO""),1,0)"),1.0) -> 1
A38: FUERZA POPULAR | B38: 45382589 | C38: ALEGRIA GARCIA, LUIS ARTURO | D38: SI | E38: CONGRESO DE LA REPÚBLICA | F38: ASISTENTE NIVEL SA-2 y TÉCNICO NIVEL ST-6 EN EL DESPACHO DEL EX CONGRESISTA LUIS GALARRETA | H38: Jr. Azángaro 468 | I38: 2013 | J38: 2016 | K38: PERU | L38: LIMA | M38: LIMA | N38: LIMA | O38: desde el 28 de agosto de 2013 en el cargo de Asistente Nivel SA-2. A partir del 1 de julio de 2014 en el cargo de técnico nivel st-6 en el Despacho del ex Congresista Luis Galarreta, cesando el 26 de julio de 2016 | P38: =IFERROR(__xludf.DUMMYFUNCTION("IF(REGEXMATCH(UPPER(E38),""CONGRESO""),1,0)"),1.0) -> 1
A39: FUERZA POPULAR | B39: 45382589 | C39: ALEGRIA GARCIA, LUIS ARTURO | D39: SI | E39: CONGRESO DE LA REPÚBLICA | F39: TECNICO NIVEL ST-6 y ASESOR NIVEL SP-9 EN EL DESPACHO DEL EX CONGRESISTA LUIS GALARRETA | H39: Jr. Azángaro 468 | I39: 2016 | J39: 2020 | K39: PERU | L39: LIMA | M39: LIMA | N39: LIMA | O39: desde el 27 de julio de 2016 en el cargo de técnico nivel st-6 en el despacho del ex Congresista Luis Galarreta. A partir del 6 de octubre de 2016 en el cargo de asesor nivel sp-9 en el despacho del ex Congresista Luis Galarreta, cesando el 6 de agosto de 2018. desde el 29 de agosto de 2018 hasta el 15 de marzo de 2020 en el cargo de asesor nivel sp-9 en el despacho del ex congresista Luis Galarreta. | P39: =IFERROR(__xludf.DUMMYFUNCTION("IF(REGEXMATCH(UPPER(E39),""CONGRESO""),1,0)"),1.0) -> 1
A40: FUERZA POPULAR | B40: 45382589 | C40: ALEGRIA GARCIA, LUIS ARTURO | D40: SI | E40: CONGRESO DE LA REPÚBLICA | F40: CONGRESISTA | G40: 20161749126 | H40: Jr. Azángaro 468 | I40: 2021 | J40: 2025 | K40: PERU | L40: LIMA | M40: LIMA | N40: LIMA | O40: periodo 2021-2026 | P40: =IFERROR(__xludf.DUMMYFUNCTION("IF(REGEXMATCH(UPPER(E40),""CONGRESO""),1,0)"),1.0) -> 1
...

Sheet PIVOT_EXPERIENCIA
A1: DNI_CANDIDATO | B1: TRABAJO ALGUNA VEZ EN CONGRESO | C1: REGISTROS CONGRESO
A2: {=UNIQUE('02 EXPERIENCIA LABORAL'!B2:B1000)} -> 29569533 | B2: =IF(SUMIF('02 EXPERIENCIA LABORAL'!B:B,A2,'02 EXPERIENCIA LABORAL'!P:P)>0,1,0) -> 0 | C2: =SUMIF('02 EXPERIENCIA LABORAL'!B:B,A2,'02 EXPERIENCIA LABORAL'!P:P) -> 0
A3: 41618961 | B3: =IF(SUMIF('02 EXPERIENCIA LABORAL'!B:B,A3,'02 EXPERIENCIA LABORAL'!P:P)>0,1,0) -> 0 | C3: =SUMIF('02 EXPERIENCIA LABORAL'!B:B,A3,'02 EXPERIENCIA LABORAL'!P:P) -> 0
A4: 43592504 | B4: =IF(SUMIF('02 EXPERIENCIA LABORAL'!B:B,A4,'02 EXPERIENCIA LABORAL'!P:P)>0,1,0) -> 0 | C4: =SUMIF('02 EXPERIENCIA LABORAL'!B:B,A4,'02 EXPERIENCIA LABORAL'!P:P) -> 0
A5: 43572794 | B5: =IF(SUMIF('02 EXPERIENCIA LABORAL'!B:B,A5,'02 EXPERIENCIA LABORAL'!P:P)>0,1,0) -> 0 | C5: =SUMIF('02 EXPERIENCIA LABORAL'!B:B,A5,'02 EXPERIENCIA LABORAL'!P:P) -> 0
A6: 45218393 | B6: =IF(SUMIF('02 EXPERIENCIA LABORAL'!B:B,A6,'02 EXPERIENCIA LABORAL'!P:P)>0,1,0) -> 0 | C6: =SUMIF('02 EXPERIENCIA LABORAL'!B:B,A6,'02 EXPERIENCIA LABORAL'!P:P) -> 0
A7: 70665764 | B7: =IF(SUMIF('02 EXPERIENCIA LABORAL'!B:B,A7,'02 EXPERIENCIA LABORAL'!P:P)>0,1,0) -> 0 | C7: =SUMIF('02 EXPERIENCIA LABORAL'!B:B,A7,'02 EXPERIENCIA LABORAL'!P:P) -> 0
A8: 41840094 | B8: =IF(SUMIF('02 EXPERIENCIA LABORAL'!B:B,A8,'02 EXPERIENCIA LABORAL'!P:P)>0,1,0) -> 0 | C8: =SUMIF('02 EXPERIENCIA LABORAL'!B:B,A8,'02 EXPERIENCIA LABORAL'!P:P) -> 0
A9: 42839004 | B9: =IF(SUMIF('02 EXPERIENCIA LABORAL'!B:B,A9,'02 EXPERIENCIA LABORAL'!P:P)>0,1,0) -> 0 | C9: =SUMIF('02 EXPERIENCIA LABORAL'!B:B,A9,'02 EXPERIENCIA LABORAL'!P:P) -> 0
A10: 46307918 | B10: =IF(SUMIF('02 EXPERIENCIA LABORAL'!B:B,A10,'02 EXPERIENCIA LABORAL'!P:P)>0,1,0) -> 0 | C10: =SUMIF('02 EXPERIENCIA LABORAL'!B:B,A10,'02 EXPERIENCIA LABORAL'!P:P) -> 0
A11: 09391698 | B11: =IF(SUMIF('02 EXPERIENCIA LABORAL'!B:B,A11,'02 EXPERIENCIA LABORAL'!P:P)>0,1,0) -> 1 | C11: =SUMIF('02 EXPERIENCIA LABORAL'!B:B,A11,'02 EXPERIENCIA LABORAL'!P:P) -> 2
A12: 45382589 | B12: =IF(SUMIF('02 EXPERIENCIA LABORAL'!B:B,A12,'02 EXPERIENCIA LABORAL'!P:P)>0,1,0) -> 1 | C12: =SUMIF('02 EXPERIENCIA LABORAL'!B:B,A12,'02 EXPERIENCIA LABORAL'!P:P) -> 5
A13: 15984771 | B13: =IF(SUMIF('02 EXPERIENCIA LABORAL'!B:B,A13,'02 EXPERIENCIA LABORAL'!P:P)>0,1,0) -> 1 | C13: =SUMIF('02 EXPERIENCIA LABORAL'!B:B,A13,'02 EXPERIENCIA LABORAL'!P:P) -> 1
A14: 76030152 | B14: =IF(SUMIF('02 EXPERIENCIA LABORAL'!B:B,A14,'02 EXPERIENCIA LABORAL'!P:P)>0,1,0) -> 1 | C14: =SUMIF('02 EXPERIENCIA LABORAL'!B:B,A14,'02 EXPERIENCIA LABORAL'!P:P) -> 3
... A101: 07026029 | B101: =IF(SUMIF('02 EXPERIENCIA LABORAL'!B:B,A101,'02 EXPERIENCIA LABORAL'!P:P)>0,1,0) -> 1 | C101: =SUMIF('02 EXPERIENCIA LABORAL'!B:B,A101,'02 EXPERIENCIA LABORAL'!P:P) -> 1
B103: =SUM(B2:B101) -> 29 | C103: =SUM(C2:C101) -> 62

Sheet 03 FORM ACADEM. - EDUC. BASICA
A1: ORGANIZACION_POLITICA | B1: DNI_CANDIDATO | C1: CANDIDATO | D1: TIENE_EDUCACION_BASICA | E1: EDUC_PRIMARIA | F1: EDUC_PRIMARIA_CONCLUIDA | G1: EDUC_SECUNDARIA | H1: EDUC_SECUNDARIA_CONCLUIDA
A2: AHORA NACION - AN | B2: 29569533 | C2: ARMINTA VALENCIA, MARLENY BIBIANA | D2: SI | E2: SI | F2: SI | G2: SI | H2: SI
A3: AHORA NACION - AN | B3: 41618961 | C3: BUITRON MARTINEZ, FRESHMAN | D3: SI | E3: SI | F3: SI | G3: SI | H3: SI
A4: AHORA NACION - AN | B4: 43592504 | C4: COLCHADO HUAMANI, HARVEY JULIO | D4: SI | E4: SI | F4: SI | G4: SI | H4: SI
A5: AHORA NACION - AN | B5: 43572794 | C5: HOLGUIN LOAIZA, CESAR AUGUSTO | D5: SI | E5: SI | F5: SI | G5: SI | H5: SI
A6: AHORA NACION - AN | B6: 45218393 | C6: HUILCA FLORES, INDIRA ISABEL | D6: SI | E6: SI | F6: SI | G6: SI | H6: SI
A7: AHORA NACION - AN | B7: 70665764 | C7: MANRIQUE OLIVERA, BERNARDINO JAIR | D7: SI | E7: SI | F7: SI | G7: SI | H7: SI
A8: AHORA NACION - AN | B8: 41840094 | C8: MARCELO SALAZAR, JOSE MIGUEL | D8: SI | E8: SI | F8: SI | G8: SI | H8: SI
A9: AHORA NACION - AN | B9: 42839004 | C9: MUEDAS BALBIESE, CESAR AUGUSTO | D9: SI | E9: SI | F9: SI | G9: SI | H9: SI
A10: AHORA NACION - AN | B10: 46307918 | C10: SONCO VILLANUEVA, HELARD BLADIMIR | D10: SI | E10: SI | F10: SI | G10: SI | H10: SI
A11: FUERZA POPULAR | B11: 09391698 | C11: ABENSUR PINASCO, JAIME AMERICO | D11: SI | E11: SI | F11: SI | G11: SI | H11: SI
A12: FUERZA POPULAR | B12: 45382589 | C12: ALEGRIA GARCIA, LUIS ARTURO | D12: SI | E12: SI | F12: SI | G12: SI | H12: SI
... A55: JUNTOS POR EL PERU | B55: 74638299 | C55: PAREDES NAVARRO, YENIFER NOELIA | D55: SI | E55: SI | F55: SI | G55: SI | H55: SI
A56: JUNTOS POR EL PERU | B56: 42135939 | C56: PEÑA CORDOVA, OLVER | D56: SI | E56: SI | G56: SI
A57: JUNTOS POR EL PERU | B57: 10536312 | C57: PEREZ MALLQUI, JULIAN LUIS | D57: SI | E57: SI | F57: SI | G57: SI | H57: SI
A58: JUNTOS POR EL PERU | B58: 44908591 | C58: PEREZ QUISPE, JESSICA SADITH | D58: SI | E58: SI | F58: SI | G58: SI | H58: SI
A59: JUNTOS POR EL PERU | B59: 42984568 | C59: POMA HUAMANI, HAYDEE CELINDA | D59: SI | E59: SI | F59: SI | G59: SI | H59: SI
A60: JUNTOS POR EL PERU | B60: 70163475 | C60: TAPULLIMA INSAPILLO, JACQUELINE VIVIANA | D60: NO
A61: JUNTOS POR EL PERU | B61: 01320941 | C61: TITO ROJAS, CESAR HUGO | D61: SI | E61: SI | F61: SI | G61: SI | H61: SI
A62: JUNTOS POR EL PERU | B62: 45327535 | C62: ZUNINI YERREN, ERNESTO ALONZO | D62: SI | E62: SI | F62: SI | G62: SI | H62: SI
A63: PARTIDO CIVICO OBRAS | B63: 46602828 | C63: ALBAÑIL CARMONA, HENRY ANTONIO | D63: SI | E63: SI | F63: SI | G63: SI | H63: SI
A64: PARTIDO CIVICO OBRAS | B64: 43170121 | C64: ALVARON DE LA CRUZ, EDGAR ADRIAN | D64: SI | E64: SI | F64: SI | G64: SI | H64: SI
A65: PARTIDO CIVICO OBRAS | B65: 00482691 | C65: CABRERA NIETO, JUAN CESAR | D65: SI | E65: SI | F65: SI | G65: SI | H65: SI
A66: PARTIDO CIVICO OBRAS | B66: 07654582 | C66: EUSEBIO PADILLA, ARTURO CESAR | D66: SI | E66: SI | F66: SI | G66: SI | H66: SI
A67: PARTIDO CIVICO OBRAS | B67: 01545223 | C67: HANCCO HANCCO, DINA IRENE | D67: SI | E67: SI | F67: SI | G67: SI | H67: SI
A68: PARTIDO CIVICO OBRAS | B68: 01545223 | C68: HANCCO HANCCO, DINA IRENE | D68: SI | E68: SI | F68: SI | G68: SI | H68: SI
A69: PARTIDO CIVICO OBRAS | B69: 25001331 | C69: LOPEZ LETONA, HEBER | D69: SI | E69: SI | F69: SI | G69: SI | H69: SI
