Workbook

Sheet 01 DATOS PERSONALES
A1: ORGANIZACION_POLITICA | B1: DNI_CANDIDATO | C1: CANDIDATO | D1: DOCUMENTO_IDENTIDAD | E1: APELLIDO_PATERNO | F1: APELLIDO_MATERNO | G1: NOMBRES | H1: SEXO | I1: FECHA_NACIMIENTO | J1: PAIS_NACIMIENTO | K1: DEPARTAMENTO_NACIMIENTO | L1: PROVINCIA_NACIMIENTO | M1: DISTRITO_NACIMIENTO | N1: PRIMER_CARGO_ELECCION | O1: SEGUNDO_CARGO_ELECION | P1: DISTRITO_ELEC | Q1: INFORMACION_COMPLEMENTARIA | R1: URL_FOTO | S1: TXRUTAVIRTUAL | T1: TXNOMBREDOCUMENTO | U1: EDAD | V1: RANGO_EDAD | W1: PAÍS_LIMPIO | X1: SEXO_LIMPIO | Y1: DEP_NAC_LIMPIO | Z1: DISTRITO_ELEC_LIMPIO
A2: AHORA NACION - AN | B2: 07755878 | C2: DELGADO ZEGARRA, JAIME RICARDO | D2: 07755878 | E2: DELGADO | F2: ZEGARRA | G2: JAIME RICARDO | H2: MASCULINO | I2: 17/11/1956 | J2: PERÚ | K2: AREQUIPA | L2: AREQUIPA | M2: AREQUIPA | N2: SENADOR | P2: ÚNICO NACIONAL | R2: https://mpesije.jne.gob.pe/apidocs/9aee4b33-103e-4327-9038-3618515d950d.jpg | S2: https://mpesije.jne.gob.pe/apidocs/bec6fc78-6285-4522-a02e-2730994b7ca8.pdf | T2: =CONCATENATE(A2," - ",B2,".pdf") -> AHORA NACION - AN - 07755878.pdf | U2: =IF(I2="","",DATEDIF(DATE(VALUE(RIGHT(I2,4)),VALUE(MID(I2,4,2)),VALUE(LEFT(I2,2))),TODAY(),"Y")) -> 69 | V2: =IF(U2="","",IF(U2<30,"18-29",IF(U2<40,"30-39",IF(U2<50,"40-49",IF(U2<60,"50-59","60+"))))) -> 60+ | W2: =IF(UPPER(TRIM(J2))="PERU","PERÚ",UPPER(TRIM(J2))) -> PERÚ | X2: =UPPER(TRIM(H2)) -> MASCULINO | Y2: =UPPER(TRIM(K2)) -> AREQUIPA | Z2: =UPPER(TRIM(P2)) -> ÚNICO NACIONAL
A3: AHORA NACION - AN | B3: 25331980 | C3: LOPEZ CHAU NAVA, PABLO ALFONSO | D3: 25331980 | E3: LOPEZ CHAU | F3: NAVA | G3: PABLO ALFONSO | H3: MASCULINO | I3: 17/07/1950 | J3: PERÚ | K3: LIMA | L3: LIMA | M3: LIMA | N3: PRESIDENTE DE LA REPÚBLICA | O3: SENADOR | P3: ÚNICO NACIONAL | R3: https://mpesije.jne.gob.pe/apidocs/ddfa74eb-cae3-401c-a34c-35543ae83c57.jpg | S3: https://mpesije.jne.gob.pe/apidocs/4ba2cdce-703e-421b-8b75-746b4dd21439.pdf | T3: =CONCATENATE(A3," - ",B3,".pdf") -> AHORA NACION - AN - 25331980.pdf | U3: =IF(I3="","",DATEDIF(DATE(VALUE(RIGHT(I3,4)),VALUE(MID(I3,4,2)),VALUE(LEFT(I3,2))),TODAY(),"Y")) -> 75 | V3: =IF(U3="","",IF(U3<30,"18-29",IF(U3<40,"30-39",IF(U3<50,"40-49",IF(U3<60,"50-59","60+"))))) -> 60+ | W3: =IF(UPPER(TRIM(J3))="PERU","PERÚ",UPPER(TRIM(J3))) -> PERÚ | X3: =UPPER(TRIM(H3)) -> MASCULINO | Y3: =UPPER(TRIM(K3)) -> LIMA | Z3: =UPPER(TRIM(P3)) -> ÚNICO NACIONAL
A4: AHORA NACION - AN | B4: 40204874 | C4: LUQUE IBARRA, RUTH | D4: 40204874 | E4: LUQUE | F4: IBARRA | G4: RUTH | H4: FEMENINO | I4: 19/06/1979 | J4: PERÚ | K4: CUSCO | L4: CUSCO | M4: SANTIAGO | N4: SENADOR | P4: ÚNICO NACIONAL | R4: https://mpesije.jne.gob.pe/apidocs/428c14a1-1be6-477e-b02a-f0dec2dc8e65.jpg | S4: https://mpesije.jne.gob.pe/apidocs/ed569772-6440-41f6-a1ad-b62d373d92ef.pdf | T4: =CONCATENATE(A4," - ",B4,".pdf") -> AHORA NACION - AN - 40204874.pdf | U4: =IF(I4="","",DATEDIF(DATE(VALUE(RIGHT(I4,4)),VALUE(MID(I4,4,2)),VALUE(LEFT(I4,2))),TODAY(),"Y")) -> 46 | V4: =IF(U4="","",IF(U4<30,"18-29",IF(U4<40,"30-39",IF(U4<50,"40-49",IF(U4<60,"50-59","60+"))))) -> 40-49 | W4: =IF(UPPER(TRIM(J4))="PERU","PERÚ",UPPER(TRIM(J4))) -> PERÚ | X4: =UPPER(TRIM(H4)) -> FEMENINO | Y4: =UPPER(TRIM(K4)) -> CUSCO | Z4: =UPPER(TRIM(P4)) -> ÚNICO NACIONAL
A5: AHORA NACION - AN | B5: 26705695 | C5: VASQUEZ CHUQUILIN, MIRTHA ESTHER | D5: 26705695 | E5: VASQUEZ | F5: CHUQUILIN | G5: MIRTHA ESTHER | H5: FEMENINO | I5: 31/03/1975 | J5: PERÚ | K5: CAJAMARCA | L5: CAJAMARCA | M5: CAJAMARCA | N5: SENADOR | P5: ÚNICO NACIONAL | R5: https://mpesije.jne.gob.pe/apidocs/83aa4be4-54a0-4f96-874a-96ec34678843.jpg | S5: https://mpesije.jne.gob.pe/apidocs/26df0361-db17-47af-85bf-fc1e8ae1329b.pdf | T5: =CONCATENATE(A5," - ",B5,".pdf") -> AHORA NACION - AN - 26705695.pdf | U5: =IF(I5="","",DATEDIF(DATE(VALUE(RIGHT(I5,4)),VALUE(MID(I5,4,2)),VALUE(LEFT(I5,2))),TODAY(),"Y")) -> 51 | V5: =IF(U5="","",IF(U5<30,"18-29",IF(U5<40,"30-39",IF(U5<50,"40-49",IF(U5<60,"50-59","60+"))))) -> 50-59 | W5: =IF(UPPER(TRIM(J5))="PERU","PERÚ",UPPER(TRIM(J5))) -> PERÚ | X5: =UPPER(TRIM(H5)) -> FEMENINO | Y5: =UPPER(TRIM(K5)) -> CAJAMARCA | Z5: =UPPER(TRIM(P5)) -> ÚNICO NACIONAL
A6: FUERZA POPULAR | B6: 08236035 | C6: AGUINAGA RECUENCO, ALEJANDRO AURELIO | D6: 08236035 | E6: AGUINAGA | F6: RECUENCO | G6: ALEJANDRO AURELIO | H6: MASCULINO | I6: 28/01/1950 | J6: PERÚ | K6: LA LIBERTAD | L6: TRUJILLO | M6: TRUJILLO | N6: SENADOR | P6: LAMBAYEQUE | R6: https://mpesije.jne.gob.pe/apidocs/ec0a8246-1b06-4e2b-8037-a71cfce09cf5.jpg | S6: https://mpesije.jne.gob.pe/apidocs/6b4456ea-6731-4925-a6e7-056a36b87156.pdf | T6: =CONCATENATE(A6," - ",B6,".pdf") -> FUERZA POPULAR - 08236035.pdf | U6: =IF(I6="","",DATEDIF(DATE(VALUE(RIGHT(I6,4)),VALUE(MID(I6,4,2)),VALUE(LEFT(I6,2))),TODAY(),"Y")) -> 76 | V6: =IF(U6="","",IF(U6<30,"18-29",IF(U6<40,"30-39",IF(U6<50,"40-49",IF(U6<60,"50-59","60+"))))) -> 60+ | W6: =IF(UPPER(TRIM(J6))="PERU","PERÚ",UPPER(TRIM(J6))) -> PERÚ | X6: =UPPER(TRIM(H6)) -> MASCULINO | Y6: =UPPER(TRIM(K6)) -> LA LIBERTAD | Z6: =UPPER(TRIM(P6)) -> LAMBAYEQUE
A7: FUERZA POPULAR | B7: 06717199 | C7: ARISTA ARBILDO, JOSE BERLEY | D7: 06717199 | E7: ARISTA | F7: ARBILDO | G7: JOSE BERLEY | H7: MASCULINO | I7: 18/08/1959 | J7: PERÚ | K7: AMAZONAS | L7: RODRIGUEZ DE MENDOZA | M7: HUAMBO | N7: SENADOR | P7: AMAZONAS | R7: https://mpesije.jne.gob.pe/apidocs/d70fc358-ff34-4dfb-99fc-2cdcbb77ff83.jpg | S7: https://mpesije.jne.gob.pe/apidocs/4239a3ba-9445-4c88-a74d-d0d798857d45.pdf | T7: =CONCATENATE(A7," - ",B7,".pdf") -> FUERZA POPULAR - 06717199.pdf | U7: =IF(I7="","",DATEDIF(DATE(VALUE(RIGHT(I7,4)),VALUE(MID(I7,4,2)),VALUE(LEFT(I7,2))),TODAY(),"Y")) -> 66 | V7: =IF(U7="","",IF(U7<30,"18-29",IF(U7<40,"30-39",IF(U7<50,"40-49",IF(U7<60,"50-59","60+"))))) -> 60+ | W7: =IF(UPPER(TRIM(J7))="PERU","PERÚ",UPPER(TRIM(J7))) -> PERÚ | X7: =UPPER(TRIM(H7)) -> MASCULINO | Y7: =UPPER(TRIM(K7)) -> AMAZONAS | Z7: =UPPER(TRIM(P7)) -> AMAZONAS
A8: FUERZA POPULAR | B8: 10307948 | C8: ASTUDILLO SALCEDO, CESAR AUGUSTO | D8: 10307948 | E8: ASTUDILLO | F8: SALCEDO | G8: CESAR AUGUSTO | H8: MASCULINO | I8: 30/09/1960 | J8: PERÚ | K8: LIMA | L8: LIMA | M8: MIRAFLORES | N8: SENADOR | P8: ÚNICO NACIONAL | R8: https://mpesije.jne.gob.pe/apidocs/e4aee02d-e85d-44f7-aaca-9eb286ee132f.jpg | S8: https://mpesije.jne.gob.pe/apidocs/c3804a57-68ff-450f-b6d6-edd5fa532e44.pdf | T8: =CONCATENATE(A8," - ",B8,".pdf") -> FUERZA POPULAR - 10307948.pdf | U8: =IF(I8="","",DATEDIF(DATE(VALUE(RIGHT(I8,4)),VALUE(MID(I8,4,2)),VALUE(LEFT(I8,2))),TODAY(),"Y")) -> 65 | V8: =IF(U8="","",IF(U8<30,"18-29",IF(U8<40,"30-39",IF(U8<50,"40-49",IF(U8<60,"50-59","60+"))))) -> 60+ | W8: =IF(UPPER(TRIM(J8))="PERU","PERÚ",UPPER(TRIM(J8))) -> PERÚ | X8: =UPPER(TRIM(H8)) -> MASCULINO | Y8: =UPPER(TRIM(K8)) -> LIMA | Z8: =UPPER(TRIM(P8)) -> ÚNICO NACIONAL
A9: FUERZA POPULAR | B9: 32971154 | C9: CHACON TRUJILLO, NILZA MERLY | D9: 32971154 | E9: CHACON | F9: TRUJILLO | G9: NILZA MERLY | H9: FEMENINO | I9: 15/12/1975 | J9: PERÚ | K9: ANCASH | L9: SANTA | M9: CHIMBOTE | N9: SENADOR | P9: ANCASH | R9: https://mpesije.jne.gob.pe/apidocs/133f5d7c-5498-4a5e-81e2-a7c2f3f53d0c.jpg | S9: https://mpesije.jne.gob.pe/apidocs/647e50c4-80ae-491f-9f49-ead290ebba04.pdf | T9: =CONCATENATE(A9," - ",B9,".pdf") -> FUERZA POPULAR - 32971154.pdf | U9: =IF(I9="","",DATEDIF(DATE(VALUE(RIGHT(I9,4)),VALUE(MID(I9,4,2)),VALUE(LEFT(I9,2))),TODAY(),"Y")) -> 50 | V9: =IF(U9="","",IF(U9<30,"18-29",IF(U9<40,"30-39",IF(U9<50,"40-49",IF(U9<60,"50-59","60+"))))) -> 50-59 | W9: =IF(UPPER(TRIM(J9))="PERU","PERÚ",UPPER(TRIM(J9))) -> PERÚ | X9: =UPPER(TRIM(H9)) -> FEMENINO | Y9: =UPPER(TRIM(K9)) -> ANCASH | Z9: =UPPER(TRIM(P9)) -> ANCASH
A10: FUERZA POPULAR | B10: 07960843 | C10: CHAVEZ COSSIO, MARTHA GLADYS | D10: 07960843 | E10: CHAVEZ | F10: COSSIO | G10: MARTHA GLADYS | H10: FEMENINO | I10: 12/01/1953 | J10: PERÚ | K10: CALLAO | L10: CALLAO | M10: BELLAVISTA | N10: SENADOR | P10: ÚNICO NACIONAL | Q10: Callao no es departamento. Debería figurar como "provincia constitucional del Callao". | R10: https://mpesije.jne.gob.pe/apidocs/b3b29de8-c5bd-4b73-b34b-29c48267363a.jpg | S10: https://mpesije.jne.gob.pe/apidocs/cd58063a-eafa-4e92-b04e-267a33eda88b.pdf | T10: =CONCATENATE(A10," - ",B10,".pdf") -> FUERZA POPULAR - 07960843.pdf | U10: =IF(I10="","",DATEDIF(DATE(VALUE(RIGHT(I10,4)),VALUE(MID(I10,4,2)),VALUE(LEFT(I10,2))),TODAY(),"Y")) -> 73 | V10: =IF(U10="","",IF(U10<30,"18-29",IF(U10<40,"30-39",IF(U10<50,"40-49",IF(U10<60,"50-59","60+"))))) -> 60+ | W10: =IF(UPPER(TRIM(J10))="PERU","PERÚ",UPPER(TRIM(J10))) -> PERÚ | X10: =UPPER(TRIM(H10)) -> FEMENINO | Y10: =UPPER(TRIM(K10)) -> CALLAO | Z10: =UPPER(TRIM(P10)) -> ÚNICO NACIONAL
A11: FUERZA POPULAR | B11: 05227631 | C11: DEL AGUILA CARDENAS, JUAN CARLOS | D11: 05227631 | E11: DEL AGUILA | F11: CARDENAS | G11: JUAN CARLOS | H11: MASCULINO | I11: 09/01/1962 | J11: PERÚ | K11: LORETO | L11: MAYNAS | M11: IQUITOS | N11: SENADOR | P11: LORETO | R11: https://mpesije.jne.gob.pe/apidocs/39addd4e-6c93-405b-9e93-56a0892eae72.jpg | S11: https://mpesije.jne.gob.pe/apidocs/f2c9c961-f74a-45e8-8790-d864e7893093.pdf | T11: =CONCATENATE(A11," - ",B11,".pdf") -> FUERZA POPULAR - 05227631.pdf | U11: =IF(I11="","",DATEDIF(DATE(VALUE(RIGHT(I11,4)),VALUE(MID(I11,4,2)),VALUE(LEFT(I11,2))),TODAY(),"Y")) -> 64 | V11: =IF(U11="","",IF(U11<30,"18-29",IF(U11<40,"30-39",IF(U11<50,"40-49",IF(U11<60,"50-59","60+"))))) -> 60+ | W11: =IF(UPPER(TRIM(J11))="PERU","PERÚ",UPPER(TRIM(J11))) -> PERÚ | X11: =UPPER(TRIM(H11)) -> MASCULINO | Y11: =UPPER(TRIM(K11)) -> LORETO | Z11: =UPPER(TRIM(P11)) -> LORETO
A12: FUERZA POPULAR | B12: 17896798 | C12: FLORES RUIZ, VICTOR SEFERINO | D12: 17896798 | E12: FLORES | F12: RUIZ | G12: VICTOR SEFERINO | H12: MASCULINO | I12: 24/08/1957 | J12: PERÚ | K12: LA LIBERTAD | L12: SANCHEZ CARRION | M12: HUAMACHUCO | N12: SENADOR | P12: LA LIBERTAD | R12: https://mpesije.jne.gob.pe/apidocs/8022ae32-73db-492b-9442-9ab351cf4ac6.jpg | S12: https://mpesije.jne.gob.pe/apidocs/c913c7f0-9803-46c8-8b69-d37a3f7b5206.pdf | T12: =CONCATENATE(A12," - ",B12,".pdf") -> FUERZA POPULAR - 17896798.pdf | U12: =IF(I12="","",DATEDIF(DATE(VALUE(RIGHT(I12,4)),VALUE(MID(I12,4,2)),VALUE(LEFT(I12,2))),TODAY(),"Y")) -> 68 | V12: =IF(U12="","",IF(U12<30,"18-29",IF(U12<40,"30-39",IF(U12<50,"40-49",IF(U12<60,"50-59","60+"))))) -> 60+ | W12: =IF(UPPER(TRIM(J12))="PERU","PERÚ",UPPER(TRIM(J12))) -> PERÚ | X12: =UPPER(TRIM(H12)) -> MASCULINO | Y12: =UPPER(TRIM(K12)) -> LA LIBERTAD | Z12: =UPPER(TRIM(P12)) -> LA LIBERTAD
A13: FUERZA POPULAR | B13: 19994639 | C13: JIMENEZ HEREDIA, DAVID JULIO | D13: 19994639 | E13: JIMENEZ | F13: HEREDIA | G13: DAVID JULIO | H13: MASCULINO | I13: 01/09/1955 | J13: PERÚ | K13: JUNIN | L13: HUANCAYO | M13: HUANCAYO | N13: SENADOR | P13: JUNIN | R13: https://mpesije.jne.gob.pe/apidocs/2856fdf9-9f1e-4e3e-857e-0b998e066e36.jpg | S13: https://mpesije.jne.gob.pe/apidocs/e234be5e-855f-4d56-9ed4-0849690ccbf5.pdf | T13: =CONCATENATE(A13," - ",B13,".pdf") -> FUERZA POPULAR - 19994639.pdf | U13: =IF(I13="","",DATEDIF(DATE(VALUE(RIGHT(I13,4)),VALUE(MID(I13,4,2)),VALUE(LEFT(I13,2))),TODAY(),"Y")) -> 70 | V13: =IF(U13="","",IF(U13<30,"18-29",IF(U13<40,"30-39",IF(U13<50,"40-49",IF(U13<60,"50-59","60+"))))) -> 60+ | W13: =IF(UPPER(TRIM(J13))="PERU","PERÚ",UPPER(TRIM(J13))) -> PERÚ | X13: =UPPER(TRIM(H13)) -> MASCULINO | Y13: =UPPER(TRIM(K13)) -> JUNIN | Z13: =UPPER(TRIM(P13)) -> JUNIN
A14: FUERZA POPULAR | B14: 07831436 | C14: JUAREZ GALLEGOS, CARMEN PATRICIA | D14: 07831436 | E14: JUAREZ | F14: GALLEGOS | G14: CARMEN PATRICIA | H14: FEMENINO | I14: 16/07/1960 | J14: PERÚ | K14: ICA | L14: NASCA | M14: MARCONA | N14: SENADOR | P14: ÚNICO NACIONAL | R14: https://mpesije.jne.gob.pe/apidocs/1dc6fbdd-d970-4fa3-9195-cf0492bc11d2.jpg | S14: https://mpesije.jne.gob.pe/apidocs/f7c8bd65-b17e-4266-845d-b045a55d492a.pdf | T14: =CONCATENATE(A14," - ",B14,".pdf") -> FUERZA POPULAR - 07831436.pdf | U14: =IF(I14="","",DATEDIF(DATE(VALUE(RIGHT(I14,4)),VALUE(MID(I14,4,2)),VALUE(LEFT(I14,2))),TODAY(),"Y")) -> 65 | V14: =IF(U14="","",IF(U14<30,"18-29",IF(U14<40,"30-39",IF(U14<50,"40-49",IF(U14<60,"50-59","60+"))))) -> 60+ | W14: =IF(UPPER(TRIM(J14))="PERU","PERÚ",UPPER(TRIM(J14))) -> PERÚ | X14: =UPPER(TRIM(H14)) -> FEMENINO | Y14: =UPPER(TRIM(K14)) -> ICA | Z14: =UPPER(TRIM(P14)) -> ÚNICO NACIONAL
A15: FUERZA POPULAR | B15: 09884301 | C15: MELGAR VALDEZ, ELARD GALO | D15: 09884301 | E15: MELGAR | F15: VALDEZ | G15: ELARD GALO | H15: MASCULINO | I15: 15/10/1956 | J15: PERÚ | K15: AREQUIPA | L15: CASTILLA | M15: APLAO | N15: SENADOR | P15: LIMA PROVINCIAS | R15: https://mpesije.jne.gob.pe/apidocs/2d527059-8586-4a8d-9224-a08d4d3dc223.jpg | S15: https://mpesije.jne.gob.pe/apidocs/a0e3bdcd-8a71-4f70-a1d5-aebd9d0c263a.pdf | T15: =CONCATENATE(A15," - ",B15,".pdf") -> FUERZA POPULAR - 09884301.pdf | U15: =IF(I15="","",DATEDIF(DATE(VALUE(RIGHT(I15,4)),VALUE(MID(I15,4,2)),VALUE(LEFT(I15,2))),TODAY(),"Y")) -> 69 | V15: =IF(U15="","",IF(U15<30,"18-29",IF(U15<40,"30-39",IF(U15<50,"40-49",IF(U15<60,"50-59","60+"))))) -> 60+ | W15: =IF(UPPER(TRIM(J15))="PERU","PERÚ",UPPER(TRIM(J15))) -> PERÚ | X15: =UPPER(TRIM(H15)) -> MASCULINO | Y15: =UPPER(TRIM(K15)) -> AREQUIPA | Z15: =UPPER(TRIM(P15)) -> LIMA PROVINCIAS
A16: FUERZA POPULAR | B16: 08266314 | C16: MESIA RAMIREZ, CARLOS FERNANDO | D16: 08266314 | E16: MESIA | F16: RAMIREZ | G16: CARLOS FERNANDO | H16: MASCULINO | I16: 08/12/1959 | J16: PERÚ | K16: LORETO | L16: MAYNAS | M16: IQUITOS | N16: SENADOR | P16: ÚNICO NACIONAL | R16: https://mpesije.jne.gob.pe/apidocs/8b5d10f4-a0ec-4744-b29f-59271274b78c.jpg | S16: https://mpesije.jne.gob.pe/apidocs/986de612-7510-4a49-bbd3-8d3ff2e98d15.pdf | T16: =CONCATENATE(A16," - ",B16,".pdf") -> FUERZA POPULAR - 08266314.pdf | U16: =IF(I16="","",DATEDIF(DATE(VALUE(RIGHT(I16,4)),VALUE(MID(I16,4,2)),VALUE(LEFT(I16,2))),TODAY(),"Y")) -> 66 | V16: =IF(U16="","",IF(U16<30,"18-29",IF(U16<40,"30-39",IF(U16<50,"40-49",IF(U16<60,"50-59","60+"))))) -> 60+ | W16: =IF(UPPER(TRIM(J16))="PERU","PERÚ",UPPER(TRIM(J16))) -> PERÚ | X16: =UPPER(TRIM(H16)) -> MASCULINO | Y16: =UPPER(TRIM(K16)) -> LORETO | Z16: =UPPER(TRIM(P16)) -> ÚNICO NACIONAL
A17: FUERZA POPULAR | B17: 22974228 | C17: MIYASHIRO ARASHIRO, MARCO ENRIQUE | D17: 22974228 | E17: MIYASHIRO | F17: ARASHIRO | G17: MARCO ENRIQUE | H17: MASCULINO | I17: 25/04/1953 | J17: PERÚ | K17: LIMA | L17: LIMA | M17: LIMA | N17: SENADOR | P17: LIMA METROPOLITANA | R17: https://mpesije.jne.gob.pe/apidocs/8388c289-7fce-48e9-91f9-732565b127c7.jpg | S17: https://mpesije.jne.gob.pe/apidocs/a49ce4d3-07d3-4728-a386-78e3a7696cd2.pdf | T17: =CONCATENATE(A17," - ",B17,".pdf") -> FUERZA POPULAR - 22974228.pdf | U17: =IF(I17="","",DATEDIF(DATE(VALUE(RIGHT(I17,4)),VALUE(MID(I17,4,2)),VALUE(LEFT(I17,2))),TODAY(),"Y")) -> 73 | V17: =IF(U17="","",IF(U17<30,"18-29",IF(U17<40,"30-39",IF(U17<50,"40-49",IF(U17<60,"50-59","60+"))))) -> 60+ | W17: =IF(UPPER(TRIM(J17))="PERU","PERÚ",UPPER(TRIM(J17))) -> PERÚ | X17: =UPPER(TRIM(H17)) -> MASCULINO | Y17: =UPPER(TRIM(K17)) -> LIMA | Z17: =UPPER(TRIM(P17)) -> LIMA METROPOLITANA
A18: FUERZA POPULAR | B18: 08911520 | C18: MOYANO DELGADO, MARTHA LUPE | D18: 08911520 | E18: MOYANO | F18: DELGADO | G18: MARTHA LUPE | H18: FEMENINO | I18: 14/10/1964 | J18: PERÚ | K18: CALLAO | L18: CALLAO | M18: BELLAVISTA | N18: SENADOR | P18: ÚNICO NACIONAL | R18: https://mpesije.jne.gob.pe/apidocs/e1193269-c9d9-48c8-9ff2-4fa1317c49cf.jpg | S18: https://mpesije.jne.gob.pe/apidocs/68a5f54c-a9f2-41e8-915f-4b14a17dc3a3.pdf | T18: =CONCATENATE(A18," - ",B18,".pdf") -> FUERZA POPULAR - 08911520.pdf | U18: =IF(I18="","",DATEDIF(DATE(VALUE(RIGHT(I18,4)),VALUE(MID(I18,4,2)),VALUE(LEFT(I18,2))),TODAY(),"Y")) -> 61 | V18: =IF(U18="","",IF(U18<30,"18-29",IF(U18<40,"30-39",IF(U18<50,"40-49",IF(U18<60,"50-59","60+"))))) -> 60+ | W18: =IF(UPPER(TRIM(J18))="PERU","PERÚ",UPPER(TRIM(J18))) -> PERÚ | X18: =UPPER(TRIM(H18)) -> FEMENINO | Y18: =UPPER(TRIM(K18)) -> CALLAO | Z18: =UPPER(TRIM(P18)) -> ÚNICO NACIONAL
A19: FUERZA POPULAR | B19: 17806760 | C19: NORIEGA REATEGUI, VICTOR MANUEL | D19: 17806760 | E19: NORIEGA | F19: REATEGUI | G19: VICTOR MANUEL | H19: MASCULINO | I19: 14/05/1962 | J19: PERÚ | K19: SAN MARTIN | L19: EL DORADO | M19: SAN JOSE DE SISA | N19: SENADOR | P19: SAN MARTIN | R19: https://mpesije.jne.gob.pe/apidocs/84f8ce01-b3ad-4d93-bbe2-79314b572334.jpg | S19: https://mpesije.jne.gob.pe/apidocs/f4f1e141-61f6-4499-bf91-10e28fe56db1.pdf | T19: =CONCATENATE(A19," - ",B19,".pdf") -> FUERZA POPULAR - 17806760.pdf | U19: =IF(I19="","",DATEDIF(DATE(VALUE(RIGHT(I19,4)),VALUE(MID(I19,4,2)),VALUE(LEFT(I19,2))),TODAY(),"Y")) -> 64 | V19: =IF(U19="","",IF(U19<30,"18-29",IF(U19<40,"30-39",IF(U19<50,"40-49",IF(U19<60,"50-59","60+"))))) -> 60+ | W19: =IF(UPPER(TRIM(J19))="PERU","PERÚ",UPPER(TRIM(J19))) -> PERÚ | X19: =UPPER(TRIM(H19)) -> MASCULINO | Y19: =UPPER(TRIM(K19)) -> SAN MARTIN | Z19: =UPPER(TRIM(P19)) -> SAN MARTIN
A20: FUERZA POPULAR | B20: 08234063 | C20: RODRICH ACKERMAN, JACQUES SALOMON | D20: 08234063 | E20: RODRICH | F20: ACKERMAN | G20: JACQUES SALOMON | H20: MASCULINO | I20: 14/08/1961 | J20: PERÚ | K20: LIMA | L20: LIMA | M20: SAN ISIDRO | N20: SENADOR | P20: CALLAO | Q20: El candidato actualmente consigna en su Documento Nacional de Identidad como domicilio calle Alberto Secada N° 315 - Callao | R20: https://mpesije.jne.gob.pe/apidocs/04696b3b-471f-462a-b3c2-84726b866a6f.jpg | S20: https://mpesije.jne.gob.pe/apidocs/b368d19a-c667-4b25-9d4f-8e5048887a4f.pdf | T20: =CONCATENATE(A20," - ",B20,".pdf") -> FUERZA POPULAR - 08234063.pdf | U20: =IF(I20="","",DATEDIF(DATE(VALUE(RIGHT(I20,4)),VALUE(MID(I20,4,2)),VALUE(LEFT(I20,2))),TODAY(),"Y")) -> 64 | V20: =IF(U20="","",IF(U20<30,"18-29",IF(U20<40,"30-39",IF(U20<50,"40-49",IF(U20<60,"50-59","60+"))))) -> 60+ | W20: =IF(UPPER(TRIM(J20))="PERU","PERÚ",UPPER(TRIM(J20))) -> PERÚ | X20: =UPPER(TRIM(H20)) -> MASCULINO | Y20: =UPPER(TRIM(K20)) -> LIMA | Z20: =UPPER(TRIM(P20)) -> CALLAO
A21: FUERZA POPULAR | B21: 07704730 | C21: ROSPIGLIOSI CAPURRO, FERNANDO MIGUEL | D21: 07704730 | E21: ROSPIGLIOSI | F21: CAPURRO | G21: FERNANDO MIGUEL | H21: MASCULINO | I21: 25/02/1947 | J21: PERÚ | K21: LIMA | L21: LIMA | M21: MIRAFLORES | N21: SENADOR | P21: ÚNICO NACIONAL | R21: https://mpesije.jne.gob.pe/apidocs/4e1024fa-a2ee-4b49-8563-7484061f3763.jpg | S21: https://mpesije.jne.gob.pe/apidocs/e088f78d-87d9-4d2c-a3a9-d348a26419b4.pdf | T21: =CONCATENATE(A21," - ",B21,".pdf") -> FUERZA POPULAR - 07704730.pdf | U21: =IF(I21="","",DATEDIF(DATE(VALUE(RIGHT(I21,4)),VALUE(MID(I21,4,2)),VALUE(LEFT(I21,2))),TODAY(),"Y")) -> 79 | V21: =IF(U21="","",IF(U21<30,"18-29",IF(U21<40,"30-39",IF(U21<50,"40-49",IF(U21<60,"50-59","60+"))))) -> 60+ | W21: =IF(UPPER(TRIM(J21))="PERU","PERÚ",UPPER(TRIM(J21))) -> PERÚ | X21: =UPPER(TRIM(H21)) -> MASCULINO | Y21: =UPPER(TRIM(K21)) -> LIMA | Z21: =UPPER(TRIM(P21)) -> ÚNICO NACIONAL
A22: FUERZA POPULAR | B22: 10638205 | C22: SCHAEFER CUCULIZA, KARLA MELISSA | D22: 10638205 | E22: SCHAEFER | F22: CUCULIZA | G22: KARLA MELISSA | H22: FEMENINO | I22: 14/03/1966 | J22: PERÚ | K22: PIURA | L22: PIURA | M22: PIURA | N22: SENADOR | P22: PIURA | R22: https://mpesije.jne.gob.pe/apidocs/8484cd8e-5f0a-48d3-ba54-be7120b1107f.jpg | S22: https://mpesije.jne.gob.pe/apidocs/82e3af5f-ed4b-423d-bba6-e9de26662f1a.pdf | T22: =CONCATENATE(A22," - ",B22,".pdf") -> FUERZA POPULAR - 10638205.pdf | U22: =IF(I22="","",DATEDIF(DATE(VALUE(RIGHT(I22,4)),VALUE(MID(I22,4,2)),VALUE(LEFT(I22,2))),TODAY(),"Y")) -> 60 | V22: =IF(U22="","",IF(U22<30,"18-29",IF(U22<40,"30-39",IF(U22<50,"40-49",IF(U22<60,"50-59","60+"))))) -> 60+ | W22: =IF(UPPER(TRIM(J22))="PERU","PERÚ",UPPER(TRIM(J22))) -> PERÚ | X22: =UPPER(TRIM(H22)) -> FEMENINO | Y22: =UPPER(TRIM(K22)) -> PIURA | Z22: =UPPER(TRIM(P22)) -> PIURA
A23: FUERZA POPULAR | B23: 16657841 | C23: TAPIA BERNAL, SEGUNDO LEOCADIO | D23: 16657841 | E23: TAPIA | F23: BERNAL | G23: SEGUNDO LEOCADIO | H23: MASCULINO | I23: 12/02/1968 | J23: PERÚ | K23: CAJAMARCA | L23: CHOTA | M23: CHOTA | N23: SENADOR | P23: CAJAMARCA | R23: https://mpesije.jne.gob.pe/apidocs/09f4526f-7117-476b-9499-38179dd8ef02.jpg | S23: https://mpesije.jne.gob.pe/apidocs/3f910188-c6ed-44e3-93a5-a8fdeb7a3531.pdf | T23: =CONCATENATE(A23," - ",B23,".pdf") -> FUERZA POPULAR - 16657841.pdf | U23: =IF(I23="","",DATEDIF(DATE(VALUE(RIGHT(I23,4)),VALUE(MID(I23,4,2)),VALUE(LEFT(I23,2))),TODAY(),"Y")) -> 58 | V23: =IF(U23="","",IF(U23<30,"18-29",IF(U23<40,"30-39",IF(U23<50,"40-49",IF(U23<60,"50-59","60+"))))) -> 50-59 | W23: =IF(UPPER(TRIM(J23))="PERU","PERÚ",UPPER(TRIM(J23))) -> PERÚ | X23: =UPPER(TRIM(H23)) -> MASCULINO | Y23: =UPPER(TRIM(K23)) -> CAJAMARCA | Z23: =UPPER(TRIM(P23)) -> CAJAMARCA
A24: FUERZA POPULAR | B24: 21143880 | C24: VELASQUEZ PORTOCARRERO, JORGE | D24: 21143880 | E24: VELASQUEZ | F24: PORTOCARRERO | G24: JORGE | H24: MASCULINO | I24: 14/01/1966 | J24: PERÚ | K24: SAN MARTIN | L24: RIOJA | M24: RIOJA | N24: SENADOR | P24: UCAYALI | R24: https://mpesije.jne.gob.pe/apidocs/043cb739-9e01-4351-88d8-c0a5979b4884.jpg | S24: https://mpesije.jne.gob.pe/apidocs/764aa850-dece-4ab5-8956-4420b2717ec3.pdf | T24: =CONCATENATE(A24," - ",B24,".pdf") -> FUERZA POPULAR - 21143880.pdf | U24: =IF(I24="","",DATEDIF(DATE(VALUE(RIGHT(I24,4)),VALUE(MID(I24,4,2)),VALUE(LEFT(I24,2))),TODAY(),"Y")) -> 60 | V24: =IF(U24="","",IF(U24<30,"18-29",IF(U24<40,"30-39",IF(U24<50,"40-49",IF(U24<60,"50-59","60+"))))) -> 60+ | W24: =IF(UPPER(TRIM(J24))="PERU","PERÚ",UPPER(TRIM(J24))) -> PERÚ | X24: =UPPER(TRIM(H24)) -> MASCULINO | Y24: =UPPER(TRIM(K24)) -> SAN MARTIN | Z24: =UPPER(TRIM(P24)) -> UCAYALI
A25: FUERZA POPULAR | B25: 40242430 | C25: VENTURA ANGEL, HECTOR JOSE | D25: 40242430 | E25: VENTURA | F25: ANGEL | G25: HECTOR JOSE | H25: MASCULINO | I25: 24/07/1979 | J25: PERÚ | K25: PASCO | L25: PASCO | M25: HUARIACA | N25: SENADOR | P25: TUMBES | R25: https://mpesije.jne.gob.pe/apidocs/bcf4cec7-d78a-4d75-a07c-d6ecf3f9322e.jpg | S25: https://mpesije.jne.gob.pe/apidocs/b003710f-1e5d-4c02-bbca-7b10f0cca71a.pdf | T25: =CONCATENATE(A25," - ",B25,".pdf") -> FUERZA POPULAR - 40242430.pdf | U25: =IF(I25="","",DATEDIF(DATE(VALUE(RIGHT(I25,4)),VALUE(MID(I25,4,2)),VALUE(LEFT(I25,2))),TODAY(),"Y")) -> 46 | V25: =IF(U25="","",IF(U25<30,"18-29",IF(U25<40,"30-39",IF(U25<50,"40-49",IF(U25<60,"50-59","60+"))))) -> 40-49 | W25: =IF(UPPER(TRIM(J25))="PERU","PERÚ",UPPER(TRIM(J25))) -> PERÚ | X25: =UPPER(TRIM(H25)) -> MASCULINO | Y25: =UPPER(TRIM(K25)) -> PASCO | Z25: =UPPER(TRIM(P25)) -> TUMBES
A26: FUERZA POPULAR | B26: 21414172 | C26: YAMASHIRO ORE, RAFAEL GUSTAVO | D26: 21414172 | E26: YAMASHIRO | F26: ORE | G26: RAFAEL GUSTAVO | H26: MASCULINO | I26: 25/06/1963 | J26: PERÚ | K26: ICA | L26: ICA | M26: ICA | N26: SENADOR | P26: ICA | R26: https://mpesije.jne.gob.pe/apidocs/54b17e85-5ae3-4825-85d3-be4a29802a84.jpg | S26: https://mpesije.jne.gob.pe/apidocs/dd0973d2-282d-4388-8bf1-5f081177d22a.pdf | T26: =CONCATENATE(A26," - ",B26,".pdf") -> FUERZA POPULAR - 21414172.pdf | U26: =IF(I26="","",DATEDIF(DATE(VALUE(RIGHT(I26,4)),VALUE(MID(I26,4,2)),VALUE(LEFT(I26,2))),TODAY(),"Y")) -> 62 | V26: =IF(U26="","",IF(U26<30,"18-29",IF(U26<40,"30-39",IF(U26<50,"40-49",IF(U26<60,"50-59","60+"))))) -> 60+ | W26: =IF(UPPER(TRIM(J26))="PERU","PERÚ",UPPER(TRIM(J26))) -> PERÚ | X26: =UPPER(TRIM(H26)) -> MASCULINO | Y26: =UPPER(TRIM(K26)) -> ICA | Z26: =UPPER(TRIM(P26)) -> ICA
A27: JUNTOS POR EL PERU | B27: 22482738 | C27: ANDRES LUJAN, SERAFIN | D27: 22482738 | E27: ANDRES | F27: LUJAN | G27: SERAFIN | H27: MASCULINO | I27: 12/10/1966 | J27: PERÚ | K27: HUANUCO | L27: YAROWILCA | M27: APARICIO POMARES | N27: SENADOR | P27: HUANUCO | R27: https://mpesije.jne.gob.pe/apidocs/28f4e30f-f8c9-4a48-b698-94f4480bd3fe.jpg | S27: https://mpesije.jne.gob.pe/apidocs/5110bbb9-f342-40ef-8b4b-e6beb36c0f94.pdf | T27: =CONCATENATE(A27," - ",B27,".pdf") -> JUNTOS POR EL PERU - 22482738.pdf | U27: =IF(I27="","",DATEDIF(DATE(VALUE(RIGHT(I27,4)),VALUE(MID(I27,4,2)),VALUE(LEFT(I27,2))),TODAY(),"Y")) -> 59 | V27: =IF(U27="","",IF(U27<30,"18-29",IF(U27<40,"30-39",IF(U27<50,"40-49",IF(U27<60,"50-59","60+"))))) -> 50-59 | W27: =IF(UPPER(TRIM(J27))="PERU","PERÚ",UPPER(TRIM(J27))) -> PERÚ | X27: =UPPER(TRIM(H27)) -> MASCULINO | Y27: =UPPER(TRIM(K27)) -> HUANUCO | Z27: =UPPER(TRIM(P27)) -> HUANUCO
A28: JUNTOS POR EL PERU | B28: 21487528 | C28: ARMACANQUI MORALES, SAUL ANDRES | D28: 21487528 | E28: ARMACANQUI | F28: MORALES | G28: SAUL ANDRES | H28: MASCULINO | I28: 30/11/1953 | J28: PERÚ | K28: ICA | L28: ICA | M28: ICA | N28: SENADOR | P28: ÚNICO NACIONAL | R28: https://mpesije.jne.gob.pe/apidocs/1baf3ce6-bf7f-4f48-90af-7df69ba21d70.jpg | S28: https://mpesije.jne.gob.pe/apidocs/fba5c0e0-c3b9-4c85-b049-58a2a0771bf0.pdf | T28: =CONCATENATE(A28," - ",B28,".pdf") -> JUNTOS POR EL PERU - 21487528.pdf | U28: =IF(I28="","",DATEDIF(DATE(VALUE(RIGHT(I28,4)),VALUE(MID(I28,4,2)),VALUE(LEFT(I28,2))),TODAY(),"Y")) -> 72 | V28: =IF(U28="","",IF(U28<30,"18-29",IF(U28<40,"30-39",IF(U28<50,"40-49",IF(U28<60,"50-59","60+"))))) -> 60+ | W28: =IF(UPPER(TRIM(J28))="PERU","PERÚ",UPPER(TRIM(J28))) -> PERÚ | X28: =UPPER(TRIM(H28)) -> MASCULINO | Y28: =UPPER(TRIM(K28)) -> ICA | Z28: =UPPER(TRIM(P28)) -> ÚNICO NACIONAL
A29: JUNTOS POR EL PERU | B29: 27409088 | C29: CASTILLO TERRONES, JOSE MERCEDES | D29: 27409088 | E29: CASTILLO | F29: TERRONES | G29: JOSE MERCEDES | H29: MASCULINO | I29: 24/09/1964 | J29: PERÚ | K29: CAJAMARCA | L29: CHOTA | M29: TACABAMBA | N29: SENADOR | P29: ÚNICO NACIONAL | R29: https://mpesije.jne.gob.pe/apidocs/0e2b05c2-c95a-4599-bc78-56584d571b51.jpg | S29: https://mpesije.jne.gob.pe/apidocs/61933e79-79be-45fb-9b0f-11be2bf70d02.pdf | T29: =CONCATENATE(A29," - ",B29,".pdf") -> JUNTOS POR EL PERU - 27409088.pdf | U29: =IF(I29="","",DATEDIF(DATE(VALUE(RIGHT(I29,4)),VALUE(MID(I29,4,2)),VALUE(LEFT(I29,2))),TODAY(),"Y")) -> 61 | V29: =IF(U29="","",IF(U29<30,"18-29",IF(U29<40,"30-39",IF(U29<50,"40-49",IF(U29<60,"50-59","60+"))))) -> 60+ | W29: =IF(UPPER(TRIM(J29))="PERU","PERÚ",UPPER(TRIM(J29))) -> PERÚ | X29: =UPPER(TRIM(H29)) -> MASCULINO | Y29: =UPPER(TRIM(K29)) -> CAJAMARCA | Z29: =UPPER(TRIM(P29)) -> ÚNICO NACIONAL
A30: JUNTOS POR EL PERU | B30: 40669342 | C30: CCAHUANA AYMACHOQUE, HUGO ISAAC | D30: 40669342 | E30: CCAHUANA | F30: AYMACHOQUE | G30: HUGO ISAAC | H30: MASCULINO | I30: 08/07/1978 | J30: PERÚ | K30: CUSCO | L30: CANCHIS | M30: SAN PEDRO | N30: SENADOR | P30: MADRE DE DIOS | R30: https://mpesije.jne.gob.pe/apidocs/ffc812a5-4689-4912-831a-cb0ab734f078.jpg | S30: https://mpesije.jne.gob.pe/apidocs/bbc0ceed-8cb9-4859-b242-24ff0547c996.pdf | T30: =CONCATENATE(A30," - ",B30,".pdf") -> JUNTOS POR EL PERU - 40669342.pdf | U30: =IF(I30="","",DATEDIF(DATE(VALUE(RIGHT(I30,4)),VALUE(MID(I30,4,2)),VALUE(LEFT(I30,2))),TODAY(),"Y")) -> 47 | V30: =IF(U30="","",IF(U30<30,"18-29",IF(U30<40,"30-39",IF(U30<50,"40-49",IF(U30<60,"50-59","60+"))))) -> 40-49 | W30: =IF(UPPER(TRIM(J30))="PERU","PERÚ",UPPER(TRIM(J30))) -> PERÚ | X30: =UPPER(TRIM(H30)) -> MASCULINO | Y30: =UPPER(TRIM(K30)) -> CUSCO | Z30: =UPPER(TRIM(P30)) -> MADRE DE DIOS
A31: JUNTOS POR EL PERU | B31: 04647085 | C31: CUTIPA CCAMA, VICTOR RAUL | D31: 04647085 | E31: CUTIPA | F31: CCAMA | G31: VICTOR RAUL | H31: MASCULINO | I31: 14/09/1972 | J31: PERÚ | K31: PUNO | L31: PUNO | M31: ACORA | N31: SENADOR | P31: MOQUEGUA | R31: https://mpesije.jne.gob.pe/apidocs/8a462ad7-557a-40c5-80af-4f87c81544ea.jpg | S31: https://mpesije.jne.gob.pe/apidocs/df837d7a-d815-4f7a-b9f2-39edb294f267.pdf | T31: =CONCATENATE(A31," - ",B31,".pdf") -> JUNTOS POR EL PERU - 04647085.pdf | U31: =IF(I31="","",DATEDIF(DATE(VALUE(RIGHT(I31,4)),VALUE(MID(I31,4,2)),VALUE(LEFT(I31,2))),TODAY(),"Y")) -> 53 | V31: =IF(U31="","",IF(U31<30,"18-29",IF(U31<40,"30-39",IF(U31<50,"40-49",IF(U31<60,"50-59","60+"))))) -> 50-59 | W31: =IF(UPPER(TRIM(J31))="PERU","PERÚ",UPPER(TRIM(J31))) -> PERÚ | X31: =UPPER(TRIM(H31)) -> MASCULINO | Y31: =UPPER(TRIM(K31)) -> PUNO | Z31: =UPPER(TRIM(P31)) -> MOQUEGUA
A32: JUNTOS POR EL PERU | B32: 21453924 | C32: MARAVI OLARTE, IBER ANTENOR | D32: 21453924 | E32: MARAVI | F32: OLARTE | G32: IBER ANTENOR | H32: MASCULINO | I32: 15/05/1961 | J32: PERÚ | K32: AYACUCHO | L32: HUAMANGA | M32: AYACUCHO | N32: SENADOR | P32: ÚNICO NACIONAL | R32: https://mpesije.jne.gob.pe/apidocs/9ff4f8d0-cff1-429b-b3b9-a2c9baf178cf.jpg | S32: https://mpesije.jne.gob.pe/apidocs/4080756a-aa47-451c-9ae6-ea726f4dbf37.pdf | T32: =CONCATENATE(A32," - ",B32,".pdf") -> JUNTOS POR EL PERU - 21453924.pdf | U32: =IF(I32="","",DATEDIF(DATE(VALUE(RIGHT(I32,4)),VALUE(MID(I32,4,2)),VALUE(LEFT(I32,2))),TODAY(),"Y")) -> 65 | V32: =IF(U32="","",IF(U32<30,"18-29",IF(U32<40,"30-39",IF(U32<50,"40-49",IF(U32<60,"50-59","60+"))))) -> 60+ | W32: =IF(UPPER(TRIM(J32))="PERU","PERÚ",UPPER(TRIM(J32))) -> PERÚ | X32: =UPPER(TRIM(H32)) -> MASCULINO | Y32: =UPPER(TRIM(K32)) -> AYACUCHO | Z32: =UPPER(TRIM(P32)) -> ÚNICO NACIONAL
... A38: PARTIDO CIVICO OBRAS | B38: 07651031 | C38: ASTUCURI LAURA, ROGER MIGUEL | D38: 07651031 | E38: ASTUCURI | F38: LAURA | G38: ROGER MIGUEL | H38: MASCULINO | I38: 03/09/1960 | J38: PERÚ | K38: LIMA | L38: LIMA | M38: LURIGANCHO | N38: SENADOR | P38: ÚNICO NACIONAL | R38: https://mpesije.jne.gob.pe/apidocs/ca28ff0a-b929-4dae-87b6-d49dc63f75ac.jpg | S38: https://mpesije.jne.gob.pe/apidocs/1ae39a6e-ce49-4e8d-9354-e609b53c2d20.pdf | T38: =CONCATENATE(A38," - ",B38,".pdf") -> PARTIDO CIVICO OBRAS - 07651031.pdf | U38: =IF(I38="","",DATEDIF(DATE(VALUE(RIGHT(I38,4)),VALUE(MID(I38,4,2)),VALUE(LEFT(I38,2))),TODAY(),"Y")) -> 65 | V38: =IF(U38="","",IF(U38<30,"18-29",IF(U38<40,"30-39",IF(U38<50,"40-49",IF(U38<60,"50-59","60+"))))) -> 60+ | W38: =IF(UPPER(TRIM(J38))="PERU","PERÚ",UPPER(TRIM(J38))) -> PERÚ | X38: =UPPER(TRIM(H38)) -> MASCULINO | Y38: =UPPER(TRIM(K38)) -> LIMA | Z38: =UPPER(TRIM(P38)) -> ÚNICO NACIONAL
A39: PARTIDO CIVICO OBRAS | B39: 10063223 | C39: BARRAGAN COLOMA, DANIEL HUGO | D39: 10063223 | E39: BARRAGAN | F39: COLOMA | G39: DANIEL HUGO | H39: MASCULINO | I39: 21/08/1961 | J39: PERÚ | K39: LIMA | L39: LIMA | M39: LIMA | N39: PRIMER VICEPRESIDENTE DE LA REPÚBLICA | O39: SENADOR | P39: ÚNICO NACIONAL | R39: https://mpesije.jne.gob.pe/apidocs/15595890-de24-4f14-b4f6-bd9b5e10372a.jpg | S39: https://mpesije.jne.gob.pe/apidocs/6a216000-4a97-4d48-94f0-5ac8d5186e12.pdf | T39: =CONCATENATE(A39," - ",B39,".pdf") -> PARTIDO CIVICO OBRAS - 10063223.pdf | U39: =IF(I39="","",DATEDIF(DATE(VALUE(RIGHT(I39,4)),VALUE(MID(I39,4,2)),VALUE(LEFT(I39,2))),TODAY(),"Y")) -> 64 | V39: =IF(U39="","",IF(U39<30,"18-29",IF(U39<40,"30-39",IF(U39<50,"40-49",IF(U39<60,"50-59","60+"))))) -> 60+ | W39: =IF(UPPER(TRIM(J39))="PERU","PERÚ",UPPER(TRIM(J39))) -> PERÚ | X39: =UPPER(TRIM(H39)) -> MASCULINO | Y39: =UPPER(TRIM(K39)) -> LIMA | Z39: =UPPER(TRIM(P39)) -> ÚNICO NACIONAL
A40: PARTIDO CIVICO OBRAS | B40: 07250032 | C40: FLORES CORDOVA, AGRIPINA MARIA DEL PILAR | D40: 07250032 | E40: FLORES | F40: CORDOVA | G40: AGRIPINA MARIA DEL PILAR | H40: FEMENINO | I40: 23/06/1950 | J40: PERÚ | K40: LIMA | L40: LIMA | M40: MAGDALENA DEL MAR | N40: SENADOR | P40: ÚNICO NACIONAL | R40: https://mpesije.jne.gob.pe/apidocs/1c31e830-418b-4987-adc6-47f3007dd2bb.jpg | S40: https://mpesije.jne.gob.pe/apidocs/e75ecce3-6eb6-4315-b4a5-a3755c2dce0c.pdf | T40: =CONCATENATE(A40," - ",B40,".pdf") -> PARTIDO CIVICO OBRAS - 07250032.pdf | U40: =IF(I40="","",DATEDIF(DATE(VALUE(RIGHT(I40,4)),VALUE(MID(I40,4,2)),VALUE(LEFT(I40,2))),TODAY(),"Y")) -> 75 | V40: =IF(U40="","",IF(U40<30,"18-29",IF(U40<40,"30-39",IF(U40<50,"40-49",IF(U40<60,"50-59","60+"))))) -> 60+ | W40: =IF(UPPER(TRIM(J40))="PERU","PERÚ",UPPER(TRIM(J40))) -> PERÚ | X40: =UPPER(TRIM(H40)) -> FEMENINO | Y40: =UPPER(TRIM(K40)) -> LIMA | Z40: =UPPER(TRIM(P40)) -> ÚNICO NACIONAL
A41: PARTIDO CIVICO OBRAS | B41: 07412350 | C41: GAGO RODRIGUEZ, WALTER FRANCISCO | D41: 07412350 | E41: GAGO | F41: RODRIGUEZ | G41: WALTER FRANCISCO | H41: MASCULINO | I41: 13/07/1961 | J41: PERÚ | K41: LIMA | L41: CAÑETE | M41: SAN VICENTE DE CAÑETE | N41: SENADOR | P41: ÚNICO NACIONAL | R41: https://mpesije.jne.gob.pe/apidocs/7d624b9c-c411-46c2-9368-5f1280b8646b.jpg | S41: https://mpesije.jne.gob.pe/apidocs/75515f26-f0c4-4a79-9c09-d93ed7aae1bd.pdf | T41: =CONCATENATE(A41," - ",B41,".pdf") -> PARTIDO CIVICO OBRAS - 07412350.pdf | U41: =IF(I41="","",DATEDIF(DATE(VALUE(RIGHT(I41,4)),VALUE(MID(I41,4,2)),VALUE(LEFT(I41,2))),TODAY(),"Y")) -> 64 | V41: =IF(U41="","",IF(U41<30,"18-29",IF(U41<40,"30-39",IF(U41<50,"40-49",IF(U41<60,"50-59","60+"))))) -> 60+ | W41: =IF(UPPER(TRIM(J41))="PERU","PERÚ",UPPER(TRIM(J41))) -> PERÚ | X41: =UPPER(TRIM(H41)) -> MASCULINO | Y41: =UPPER(TRIM(K41)) -> LIMA | Z41: =UPPER(TRIM(P41)) -> ÚNICO NACIONAL
A42: PARTIDO CIVICO OBRAS | B42: 00422672 | C42: TICONA COHAILA, JUANA GUISELLA | D42: 00422672 | E42: TICONA | F42: COHAILA | G42: JUANA GUISELLA | H42: FEMENINO | I42: 30/05/1963 | J42: PERÚ | K42: TACNA | L42: TACNA | M42: TACNA | N42: SENADOR | P42: TACNA | R42: https://mpesije.jne.gob.pe/apidocs/35cb22aa-fee5-4341-b50c-2eaac0ddbb13.jpg | S42: https://mpesije.jne.gob.pe/apidocs/a3916658-d255-4bd2-b224-1059d32c8bbf.pdf | T42: =CONCATENATE(A42," - ",B42,".pdf") -> PARTIDO CIVICO OBRAS - 00422672.pdf | U42: =IF(I42="","",DATEDIF(DATE(VALUE(RIGHT(I42,4)),VALUE(MID(I42,4,2)),VALUE(LEFT(I42,2))),TODAY(),"Y")) -> 63 | V42: =IF(U42="","",IF(U42<30,"18-29",IF(U42<40,"30-39",IF(U42<50,"40-49",IF(U42<60,"50-59","60+"))))) -> 60+ | W42: =IF(UPPER(TRIM(J42))="PERU","PERÚ",UPPER(TRIM(J42))) -> PERÚ | X42: =UPPER(TRIM(H42)) -> FEMENINO | Y42: =UPPER(TRIM(K42)) -> TACNA | Z42: =UPPER(TRIM(P42)) -> TACNA
A43: PARTIDO DEL BUEN GOBIERNO | B43: 06519219 | C43: BONIFAZ CARMONA, NORA | D43: 06519219 | E43: BONIFAZ | F43: CARMONA | G43: NORA | H43: FEMENINO | I43: 08/06/1954 | J43: PERÚ | K43: LIMA | L43: LIMA | M43: LIMA | N43: SENADOR | P43: LIMA METROPOLITANA | R43: https://mpesije.jne.gob.pe/apidocs/f8a01e27-807f-4d43-a555-48f03cfe5baf.jpg | S43: https://mpesije.jne.gob.pe/apidocs/d092ca57-99b7-480c-bab3-4b7d3b8114ba.pdf | T43: =CONCATENATE(A43," - ",B43,".pdf") -> PARTIDO DEL BUEN GOBIERNO - 06519219.pdf | U43: =IF(I43="","",DATEDIF(DATE(VALUE(RIGHT(I43,4)),VALUE(MID(I43,4,2)),VALUE(LEFT(I43,2))),TODAY(),"Y")) -> 72 | V43: =IF(U43="","",IF(U43<30,"18-29",IF(U43<40,"30-39",IF(U43<50,"40-49",IF(U43<60,"50-59","60+"))))) -> 60+ | W43: =IF(UPPER(TRIM(J43))="PERU","PERÚ",UPPER(TRIM(J43))) -> PERÚ | X43: =UPPER(TRIM(H43)) -> FEMENINO | Y43: =UPPER(TRIM(K43)) -> LIMA | Z43: =UPPER(TRIM(P43)) -> LIMA METROPOLITANA
A44: PARTIDO DEL BUEN GOBIERNO | B44: 43360309 | C44: CABALLERO LEON, CARLOS DAVID | D44: 43360309 | E44: CABALLERO | F44: LEON | G44: CARLOS DAVID | H44: MASCULINO | I44: 03/05/1963 | J44: PERÚ | K44: LIMA | L44: LIMA | M44: LIMA | N44: SEGUNDO VICEPRESIDENTE DE LA REPÚBLICA | O44: SENADOR | P44: ÚNICO NACIONAL | R44: https://mpesije.jne.gob.pe/apidocs/22e7b027-0df4-461c-8fd9-1bc297a95caf.jpg | S44: https://mpesije.jne.gob.pe/apidocs/b7946182-ad32-409c-bb75-9ea7498fa803.pdf | T44: =CONCATENATE(A44," - ",B44,".pdf") -> PARTIDO DEL BUEN GOBIERNO - 43360309.pdf | U44: =IF(I44="","",DATEDIF(DATE(VALUE(RIGHT(I44,4)),VALUE(MID(I44,4,2)),VALUE(LEFT(I44,2))),TODAY(),"Y")) -> 63 | V44: =IF(U44="","",IF(U44<30,"18-29",IF(U44<40,"30-39",IF(U44<50,"40-49",IF(U44<60,"50-59","60+"))))) -> 60+ | W44: =IF(UPPER(TRIM(J44))="PERU","PERÚ",UPPER(TRIM(J44))) -> PERÚ | X44: =UPPER(TRIM(H44)) -> MASCULINO | Y44: =UPPER(TRIM(K44)) -> LIMA | Z44: =UPPER(TRIM(P44)) -> ÚNICO NACIONAL
A45: PARTIDO DEL BUEN GOBIERNO | B45: 07793210 | C45: FIGALLO RIVADENEYRA, FLAVIO FELIPE | D45: 07793210 | E45: FIGALLO | F45: RIVADENEYRA | G45: FLAVIO FELIPE | H45: MASCULINO | I45: 24/12/1953 | J45: PERÚ | K45: LIMA | L45: LIMA | M45: MIRAFLORES | N45: SENADOR | P45: ÚNICO NACIONAL | R45: https://mpesije.jne.gob.pe/apidocs/3e078903-65e7-4fe8-9c87-89be503223a7.jpg | S45: https://mpesije.jne.gob.pe/apidocs/bfbc620a-52a4-4ac5-8182-621d447b7fba.pdf | T45: =CONCATENATE(A45," - ",B45,".pdf") -> PARTIDO DEL BUEN GOBIERNO - 07793210.pdf | U45: =IF(I45="","",DATEDIF(DATE(VALUE(RIGHT(I45,4)),VALUE(MID(I45,4,2)),VALUE(LEFT(I45,2))),TODAY(),"Y")) -> 72 | V45: =IF(U45="","",IF(U45<30,"18-29",IF(U45<40,"30-39",IF(U45<50,"40-49",IF(U45<60,"50-59","60+"))))) -> 60+ | W45: =IF(UPPER(TRIM(J45))="PERU","PERÚ",UPPER(TRIM(J45))) -> PERÚ | X45: =UPPER(TRIM(H45)) -> MASCULINO | Y45: =UPPER(TRIM(K45)) -> LIMA | Z45: =UPPER(TRIM(P45)) -> ÚNICO NACIONAL
...

Sheet Pivot Table 2
A1: COUNTA of DNI_CANDIDATO | B1: SEXO_LIMPIO | F1: PARIDAD
A2: ORGANIZACION_POLITICA | B2: FEMENINO | C2: MASCULINO | D2: Total general | F2: % mujeres | G2: % hombres
A3: AHORA NACION - AN | B3: 2 | C3: 2 | D3: 4 | F3: =IFERROR(COUNTIFS('01 DATOS PERSONALES'!$A:$A,$A3,'01 DATOS PERSONALES'!$H:$H,"FEMENINO")/COUNTIF('01 DATOS PERSONALES'!$A:$A,$A3),"") -> 0.5 | G3: =IFERROR(COUNTIFS('01 DATOS PERSONALES'!$A:$A,$A3,'01 DATOS PERSONALES'!$H:$H,"MASCULINO")/COUNTIF('01 DATOS PERSONALES'!$A:$A,$A3),"") -> 0.5
A4: FUERZA POPULAR | B4: 5 | C4: 16 | D4: 21 | F4: =IFERROR(COUNTIFS('01 DATOS PERSONALES'!$A:$A,$A4,'01 DATOS PERSONALES'!$H:$H,"FEMENINO")/COUNTIF('01 DATOS PERSONALES'!$A:$A,$A4),"") -> 0.22727273 | G4: =IFERROR(COUNTIFS('01 DATOS PERSONALES'!$A:$A,$A4,'01 DATOS PERSONALES'!$H:$H,"MASCULINO")/COUNTIF('01 DATOS PERSONALES'!$A:$A,$A4),"") -> 0.77272727
A5: JUNTOS POR EL PERU | B5: 1 | C5: 10 | D5: 11 | F5: =IFERROR(COUNTIFS('01 DATOS PERSONALES'!$A:$A,$A5,'01 DATOS PERSONALES'!$H:$H,"FEMENINO")/COUNTIF('01 DATOS PERSONALES'!$A:$A,$A5),"") -> 0.071428571 | G5: =IFERROR(COUNTIFS('01 DATOS PERSONALES'!$A:$A,$A5,'01 DATOS PERSONALES'!$H:$H,"MASCULINO")/COUNTIF('01 DATOS PERSONALES'!$A:$A,$A5),"") -> 0.92857143
A6: PARTIDO CIVICO OBRAS | B6: 2 | C6: 3 | D6: 5 | F6: =IFERROR(COUNTIFS('01 DATOS PERSONALES'!$A:$A,$A6,'01 DATOS PERSONALES'!$H:$H,"FEMENINO")/COUNTIF('01 DATOS PERSONALES'!$A:$A,$A6),"") -> 0.4 | G6: =IFERROR(COUNTIFS('01 DATOS PERSONALES'!$A:$A,$A6,'01 DATOS PERSONALES'!$H:$H,"MASCULINO")/COUNTIF('01 DATOS PERSONALES'!$A:$A,$A6),"") -> 0.6
A7: PARTIDO DEL BUEN GOBIERNO | B7: 3 | C7: 4 | D7: 7 | F7: =IFERROR(COUNTIFS('01 DATOS PERSONALES'!$A:$A,$A7,'01 DATOS PERSONALES'!$H:$H,"FEMENINO")/COUNTIF('01 DATOS PERSONALES'!$A:$A,$A7),"") -> 0.42857143 | G7: =IFERROR(COUNTIFS('01 DATOS PERSONALES'!$A:$A,$A7,'01 DATOS PERSONALES'!$H:$H,"MASCULINO")/COUNTIF('01 DATOS PERSONALES'!$A:$A,$A7),"") -> 0.57142857
A8: RENOVACION POPULAR | B8: 3 | C8: 5 | D8: 8 | F8: =IFERROR(COUNTIFS('01 DATOS PERSONALES'!$A:$A,$A8,'01 DATOS PERSONALES'!$H:$H,"FEMENINO")/COUNTIF('01 DATOS PERSONALES'!$A:$A,$A8),"") -> 0.375 | G8: =IFERROR(COUNTIFS('01 DATOS PERSONALES'!$A:$A,$A8,'01 DATOS PERSONALES'!$H:$H,"MASCULINO")/COUNTIF('01 DATOS PERSONALES'!$A:$A,$A8),"") -> 0.625
A9: Total general | B9: 16 | C9: 40 | D9: 56 | F9: =IFERROR(COUNTIFS('01 DATOS PERSONALES'!$A:$A,$A9,'01 DATOS PERSONALES'!$H:$H,"FEMENINO")/COUNTIF('01 DATOS PERSONALES'!$A:$A,$A9),"") | G9: =IFERROR(COUNTIFS('01 DATOS PERSONALES'!$A:$A,$A9,'01 DATOS PERSONALES'!$H:$H,"MASCULINO")/COUNTIF('01 DATOS PERSONALES'!$A:$A,$A9),"")
F10: =IFERROR(COUNTIFS('01 DATOS PERSONALES'!$A:$A,$A10,'01 DATOS PERSONALES'!$H:$H,"FEMENINO")/COUNTIF('01 DATOS PERSONALES'!$A:$A,$A10),"") | G10: =IFERROR(COUNTIFS('01 DATOS PERSONALES'!$A:$A,$A10,'01 DATOS PERSONALES'!$H:$H,"MASCULINO")/COUNTIF('01 DATOS PERSONALES'!$A:$A,$A10),"")
F11: =IFERROR(COUNTIFS('01 DATOS PERSONALES'!$A:$A,$A11,'01 DATOS PERSONALES'!$H:$H,"FEMENINO")/COUNTIF('01 DATOS PERSONALES'!$A:$A,$A11),"") | G11: =IFERROR(COUNTIFS('01 DATOS PERSONALES'!$A:$A,$A11,'01 DATOS PERSONALES'!$H:$H,"MASCULINO")/COUNTIF('01 DATOS PERSONALES'!$A:$A,$A11),"")
A13: ORGANIZACION_POLITICA | B13: AVERAGE of EDAD | C13: MAX of EDAD | D13: MIN of EDAD
A14: AHORA NACION - AN | B14: 60.25 | C14: 75 | D14: 46
A15: FUERZA POPULAR | B15: 63.863636 | C15: 79 | D15: 46
A16: JUNTOS POR EL PERU | B16: 55.571429 | C16: 72 | D16: 41
A17: PARTIDO CIVICO OBRAS | B17: 66.2 | C17: 75 | D17: 63
A18: PARTIDO DEL BUEN GOBIERNO | B18: 64.428571 | C18: 73 | D18: 53
A19: RENOVACION POPULAR | B19: 58.875 | C19: 74 | D19: 39
A20: (en blanco)
A21: Total general | B21: 61.283333 | C21: 79 | D21: 39

Sheet RESUMEN_DP
A1: Total candidatos | B1: Mujeres | C1: Hombres | D1: Edad promedio | E1: Edad mediana | F1: Edad mínima | G1: Edad máxima
A2: =COUNTA('01 DATOS PERSONALES'!B2:B1000) -> 60 | B2: =COUNTIF('01 DATOS PERSONALES'!X2:Y1000,"FEMENINO") -> 16 | C2: =COUNTIF('01 DATOS PERSONALES'!X2:Y1000,"MASCULINO") -> 44 | D2: =AVERAGE('01 DATOS PERSONALES'!U2:U1000) -> 61.283333 | E2: =MEDIAN('01 DATOS PERSONALES'!U2:U1000) -> 63.5 | F2: =MIN('01 DATOS PERSONALES'!U2:U1000) -> 39 | G2: =MAX('01 DATOS PERSONALES'!U2:U1000) -> 79

Sheet 02 EXPERIENCIA LABORAL
A1: ORGANIZACION_POLITICA | B1: DNI_CANDIDATO | C1: CANDIDATO | D1: TIENE_EXPERIENCIA_LABORAL | E1: CENTRO_TRABAJO | F1: PROFESION_OCUPACION | G1: RUC | H1: DIRECCION | I1: AÑO_DESDE | J1: AÑO_HASTA | K1: PAIS | L1: DEPARTAMENTO | M1: PROVINCIA | N1: DISTRITO | O1: INFORMACION_ADICIONAL | P1: TRABAJO_CONGRESO
A2: AHORA NACION - AN | B2: 07755878 | C2: DELGADO ZEGARRA, JAIME RICARDO | D2: SI | E2: Congreso de la República | F2: Asesor | G2: 20161749126 | H2: Av. Abancay | I2: 2024 | J2: 2025 | K2: PERU | L2: LIMA | M2: LIMA | N2: LIMA | O2: Trabajé hasta el 28 de noviembre como asesor de la comisión de defensa del consumidor. | P2: =IFERROR(__xludf.DUMMYFUNCTION("IF(REGEXMATCH(UPPER(E2),""CONGRESO""),1,0)"),1) -> 1
A3: AHORA NACION - AN | B3: 07755878 | C3: DELGADO ZEGARRA, JAIME RICARDO | D3: SI | E3: Congreso de la República | F3: Asesor | G3: 20161749126 | H3: Av. Abancay | I3: 2020 | J3: 2020 | K3: PERU | L3: LIMA | M3: LIMA | N3: LIMA | P3: =IFERROR(__xludf.DUMMYFUNCTION("IF(REGEXMATCH(UPPER(E3),""CONGRESO""),1,0)"),1) -> 1
A4: AHORA NACION - AN | B4: 07755878 | C4: DELGADO ZEGARRA, JAIME RICARDO | D4: SI | E4: Congreso de la República | F4: Congresista | G4: 20161749126 | H4: Av. Abancay | I4: 2011 | J4: 2016 | K4: PERU | L4: LIMA | M4: LIMA | N4: LIMA | P4: =IFERROR(__xludf.DUMMYFUNCTION("IF(REGEXMATCH(UPPER(E4),""CONGRESO""),1,0)"),1) -> 1
A5: AHORA NACION - AN | B5: 07755878 | C5: DELGADO ZEGARRA, JAIME RICARDO | D5: SI | E5: Defensoría del Pueblo | F5: Asesor | H5: Jirón Ucayali 394 - 398 | I5: 2021 | J5: 2021 | K5: PERU | L5: LIMA | M5: LIMA | N5: LIMA | P5: =IFERROR(__xludf.DUMMYFUNCTION("IF(REGEXMATCH(UPPER(E5),""CONGRESO""),1,0)"),0) -> 0
A6: AHORA NACION - AN | B6: 25331980 | C6: LOPEZ CHAU NAVA, PABLO ALFONSO | D6: SI | E6: Universidad Nacional de Ingeniería | F6: Director de la Escuela de Ingeniería Económica | H6: Av. Tupac Amaru 210 | I6: 2017 | J6: 2019 | K6: PERU | L6: LIMA | M6: LIMA | N6: RIMAC | P6: =IFERROR(__xludf.DUMMYFUNCTION("IF(REGEXMATCH(UPPER(E6),""CONGRESO""),1,0)"),0) -> 0
A7: AHORA NACION - AN | B7: 25331980 | C7: LOPEZ CHAU NAVA, PABLO ALFONSO | D7: SI | E7: Universidad Nacional de Ingeniería | F7: Rector | H7: Av. Tupac Amaru 210 | I7: 2021 | J7: 2025 | K7: PERU | L7: LIMA | M7: LIMA | N7: RIMAC | P7: =IFERROR(__xludf.DUMMYFUNCTION("IF(REGEXMATCH(UPPER(E7),""CONGRESO""),1,0)"),0) -> 0
A8: AHORA NACION - AN | B8: 25331980 | C8: LOPEZ CHAU NAVA, PABLO ALFONSO | D8: SI | E8: Universidad Nacional de Ingeniería | F8: Profesor Principal | H8: Av. Tupac Amaru 210 | I8: 1990 | J8: 2025 | K8: PERU | L8: LIMA | M8: LIMA | N8: RIMAC | P8: =IFERROR(__xludf.DUMMYFUNCTION("IF(REGEXMATCH(UPPER(E8),""CONGRESO""),1,0)"),0) -> 0
A9: AHORA NACION - AN | B9: 40204874 | C9: LUQUE IBARRA, RUTH | D9: SI | E9: Derechos Humanos sin Fronteras | F9: Abogada - Directora Ejecutiva | G9: 20491238764 | H9: Barrio Profesional A-8 tercer piso | I9: 2013 | J9: 2016 | K9: PERU | L9: CUSCO | M9: CUSCO | N9: CUSCO | P9: =IFERROR(__xludf.DUMMYFUNCTION("IF(REGEXMATCH(UPPER(E9),""CONGRESO""),1,0)"),0) -> 0
A10: AHORA NACION - AN | B10: 40204874 | C10: LUQUE IBARRA, RUTH | D10: SI | E10: Congreso de la República | F10: Asesora | H10: Av. Abancay S/N | I10: 2016 | J10: 2021 | K10: PERU | L10: LIMA | M10: LIMA | N10: LIMA | P10: =IFERROR(__xludf.DUMMYFUNCTION("IF(REGEXMATCH(UPPER(E10),""CONGRESO""),1,0)"),1) -> 1
A11: AHORA NACION - AN | B11: 40204874 | C11: LUQUE IBARRA, RUTH | D11: SI | E11: Congreso de la República | F11: Congresista | H11: Av. Hospicio Ruiz Dávila Jr. Ancash 369 | I11: 2021 | J11: 2025 | K11: PERU | L11: LIMA | M11: LIMA | N11: LIMA | P11: =IFERROR(__xludf.DUMMYFUNCTION("IF(REGEXMATCH(UPPER(E11),""CONGRESO""),1,0)"),1) -> 1
A12: AHORA NACION - AN | B12: 26705695 | C12: VASQUEZ CHUQUILIN, MIRTHA ESTHER | D12: SI | E12: ONG Grufides | F12: Asesor legal | G12: 20453691536 | H12: Jr Cruz de Piedra No 441 | I12: 2023 | J12: 2025 | K12: PERU | L12: CAJAMARCA | M12: CAJAMARCA | N12: CAJAMARCA | P12: =IFERROR(__xludf.DUMMYFUNCTION("IF(REGEXMATCH(UPPER(E12),""CONGRESO""),1,0)"),0) -> 0
A13: AHORA NACION - AN | B13: 26705695 | C13: VASQUEZ CHUQUILIN, MIRTHA ESTHER | D13: SI | E13: Presidencia del Consejo de Ministros | F13: Presidenta del Consejo de Ministros | H13: Jirón Carabaya Cdra. 1 S/N | I13: 2021 | J13: 2022 | K13: PERU | L13: LIMA | M13: LIMA | N13: LIMA | O13: 07/10/2021 a 30/01/2022 | P13: =IFERROR(__xludf.DUMMYFUNCTION("IF(REGEXMATCH(UPPER(E13),""CONGRESO""),1,0)"),0) -> 0
A14: AHORA NACION - AN | B14: 26705695 | C14: VASQUEZ CHUQUILIN, MIRTHA ESTHER | D14: SI | E14: Universidad de Ciencias y Humanidades | F14: Docente | H14: Av. Universitaria 5175 | I14: 2023 | J14: 2025 | K14: PERU | L14: LIMA | M14: LIMA | N14: LOS OLIVOS | P14: =IFERROR(__xludf.DUMMYFUNCTION("IF(REGEXMATCH(UPPER(E14),""CONGRESO""),1,0)"),0) -> 0
A15: AHORA NACION - AN | B15: 26705695 | C15: VASQUEZ CHUQUILIN, MIRTHA ESTHER | D15: SI | E15: Pontificia Universidad Católica del Perú | F15: Docente | H15: Av. Universitaria 1801 | I15: 2022 | J15: 2023 | K15: PERU | L15: LIMA | M15: LIMA | N15: SAN MIGUEL | P15: =IFERROR(__xludf.DUMMYFUNCTION("IF(REGEXMATCH(UPPER(E15),""CONGRESO""),1,0)"),0) -> 0
A16: AHORA NACION - AN | B16: 26705695 | C16: VASQUEZ CHUQUILIN, MIRTHA ESTHER | D16: SI | E16: Congreso de la República | F16: Congresista de la República | H16: Plaza Bolívar S/N | I16: 2020 | J16: 2021 | K16: PERU | L16: LIMA | M16: LIMA | N16: LIMA | O16: 16/03/2020 a 27/07/2021 | P16: =IFERROR(__xludf.DUMMYFUNCTION("IF(REGEXMATCH(UPPER(E16),""CONGRESO""),1,0)"),1) -> 1
A17: FUERZA POPULAR | B17: 08236035 | C17: AGUINAGA RECUENCO, ALEJANDRO AURELIO | D17: SI | E17: CONGRESO DE LA REPÚBLICA | F17: CONGRESISTA | G17: 20161749126 | H17: JR. HUALLAGA 358 - LIMA | I17: 2021 | J17: 2025 | K17: PERU | L17: LIMA | M17: LIMA | N17: LIMA | O17: CONGRESISTA EN EJERCICIO HASTA EL AÑO 2026 | P17: =IFERROR(__xludf.DUMMYFUNCTION("IF(REGEXMATCH(UPPER(E17),""CONGRESO""),1,0)"),1) -> 1
A18: FUERZA POPULAR | B18: 08236035 | C18: AGUINAGA RECUENCO, ALEJANDRO AURELIO | D18: SI | E18: HOSPITAL NACIONAL ARZOBISPO LOAYZA | F18: MÉDICO ESPECIALISTA | G18: 20154996991 | H18: AV. ALFONSO UGARTE 848 | I18: 1986 | J18: 2020 | K18: PERU | L18: LIMA | M18: LIMA | N18: LIMA | O18: MÉDICO ESPECIALISTA NIVEL 5. | P18: =IFERROR(__xludf.DUMMYFUNCTION("IF(REGEXMATCH(UPPER(E18),""CONGRESO""),1,0)"),0) -> 0
A19: FUERZA POPULAR | B19: 08236035 | C19: AGUINAGA RECUENCO, ALEJANDRO AURELIO | D19: SI | E19: UNIVERSIDAD CIENTÍFICA DEL SUR | F19: DOCENTE | G19: 20421239275 | H19: CARRETERA PANAMERICANA SUR 19. | I19: 2019 | J19: 2020 | K19: PERU | L19: LIMA | M19: LIMA | N19: VILLA EL SALVADOR | P19: =IFERROR(__xludf.DUMMYFUNCTION("IF(REGEXMATCH(UPPER(E19),""CONGRESO""),1,0)"),0) -> 0
A20: FUERZA POPULAR | B20: 06717199 | C20: ARISTA ARBILDO, JOSE BERLEY | D20: SI | E20: Ministerio de Economía y Finanzas | F20: Ministro de Estado | G20: 20131370645 | H20: Jr. Junín 319, Cercado de Lima. | I20: 2024 | J20: 2025 | K20: PERU | L20: LIMA | M20: LIMA | N20: LIMA | P20: =IFERROR(__xludf.DUMMYFUNCTION("IF(REGEXMATCH(UPPER(E20),""CONGRESO""),1,0)"),0) -> 0
A21: FUERZA POPULAR | B21: 06717199 | C21: ARISTA ARBILDO, JOSE BERLEY | D21: SI | E21: Ministerio de Educación | F21: Consultor | G21: 20131370998 | H21: Calle Del Comercio 193 | I21: 2015 | J21: 2016 | K21: PERU | L21: LIMA | M21: LIMA | N21: SAN BORJA | P21: =IFERROR(__xludf.DUMMYFUNCTION("IF(REGEXMATCH(UPPER(E21),""CONGRESO""),1,0)"),0) -> 0
A22: FUERZA POPULAR | B22: 06717199 | C22: ARISTA ARBILDO, JOSE BERLEY | D22: SI | E22: Corporación Andina de Fomento | F22: Consultor | G22: 20508260581 | H22: Av. Canaval y Moreyra 380 | I22: 2018 | J22: 2021 | K22: PERU | L22: LIMA | M22: LIMA | N22: SAN ISIDRO | O22: Consultor externo. | P22: =IFERROR(__xludf.DUMMYFUNCTION("IF(REGEXMATCH(UPPER(E22),""CONGRESO""),1,0)"),0) -> 0
A23: FUERZA POPULAR | B23: 06717199 | C23: ARISTA ARBILDO, JOSE BERLEY | D23: SI | E23: Ministerio de Agricultura y Riego | F23: Ministro de Estado | G23: 20131372931 | H23: Jirón Cahuide 805 | I23: 2018 | J23: 2018 | K23: PERU | L23: LIMA | M23: LIMA | N23: JESUS MARIA | P23: =IFERROR(__xludf.DUMMYFUNCTION("IF(REGEXMATCH(UPPER(E23),""CONGRESO""),1,0)"),0) -> 0
A24: FUERZA POPULAR | B24: 06717199 | C24: ARISTA ARBILDO, JOSE BERLEY | D24: SI | E24: Ministerio de Economía y Finanzas | F24: Asesor | G24: 20131370645 | H24: Jr. Junín 319, Cercado de Lima. | I24: 2016 | J24: 2017 | K24: PERU | L24: LIMA | M24: LIMA | N24: LIMA | P24: =IFERROR(__xludf.DUMMYFUNCTION("IF(REGEXMATCH(UPPER(E24),""CONGRESO""),1,0)"),0) -> 0
A25: FUERZA POPULAR | B25: 10307948 | C25: ASTUDILLO SALCEDO, CESAR AUGUSTO | D25: SI | E25: Comando Conjunto de las FFAA | F25: Jefe | H25: Av. Arequipa / Av. Nicolas Corpancho, Santa Beatriz | I25: 2018 | J25: 2021 | K25: PERU | L25: LIMA | M25: LIMA | N25: LIMA | P25: =IFERROR(__xludf.DUMMYFUNCTION("IF(REGEXMATCH(UPPER(E25),""CONGRESO""),1,0)"),0) -> 0
A26: FUERZA POPULAR | B26: 10307948 | C26: ASTUDILLO SALCEDO, CESAR AUGUSTO | D26: SI | E26: Ejército del Perú | F26: Inspector | H26: Cuartel General del Ejército Peruano | I26: 2016 | J26: 2017 | K26: PERU | L26: LIMA | M26: LIMA | N26: SAN BORJA | P26: =IFERROR(__xludf.DUMMYFUNCTION("IF(REGEXMATCH(UPPER(E26),""CONGRESO""),1,0)"),0) -> 0
A27: FUERZA POPULAR | B27: 10307948 | C27: ASTUDILLO SALCEDO, CESAR AUGUSTO | D27: SI | E27: Ejército del Perú | F27: Comandante | H27: Cuartel del Ejército Peruano en Pichari | I27: 2014 | J27: 2015 | K27: PERU | L27: CUSCO | M27: LA CONVENCION | N27: PICHARI | P27: =IFERROR(__xludf.DUMMYFUNCTION("IF(REGEXMATCH(UPPER(E27),""CONGRESO""),1,0)"),0) -> 0
A28: FUERZA POPULAR | B28: 10307948 | C28: ASTUDILLO SALCEDO, CESAR AUGUSTO | D28: SI | E28: Ejército del Perú | F28: Comandante General | H28: Cuartel General del Ejército Peruano | I28: 2017 | J28: 2018 | K28: PERU | L28: LIMA | M28: LIMA | N28: SAN BORJA | P28: =IFERROR(__xludf.DUMMYFUNCTION("IF(REGEXMATCH(UPPER(E28),""CONGRESO""),1,0)"),0) -> 0
A29: FUERZA POPULAR | B29: 32971154 | C29: CHACON TRUJILLO, NILZA MERLY | D29: SI | E29: INVERSIONES GENERALES AMAT SAC | F29: Gerente General | H29: Av. Pardo #1380 | I29: 2006 | J29: 2016 | K29: PERU | L29: ANCASH | M29: SANTA | N29: CHIMBOTE | O29: La empresa se encuentra de baja conforme aparece en SUNAT | P29: =IFERROR(__xludf.DUMMYFUNCTION("IF(REGEXMATCH(UPPER(E29),""CONGRESO""),1,0)"),0) -> 0
A30: FUERZA POPULAR | B30: 32971154 | C30: CHACON TRUJILLO, NILZA MERLY | D30: SI | E30: Inversiones Generales ARIBET Corporation SAC. | F30: Gerente General | H30: Av. Pardo N° 1500 | I30: 2012 | J30: 2017 | K30: PERU | L30: ANCASH | M30: SANTA | N30: CHIMBOTE | O30: La empresa se encuentra de baja conforme aparece en SUNAT | P30: =IFERROR(__xludf.DUMMYFUNCTION("IF(REGEXMATCH(UPPER(E30),""CONGRESO""),1,0)"),0) -> 0
A31: FUERZA POPULAR | B31: 32971154 | C31: CHACON TRUJILLO, NILZA MERLY | D31: SI | E31: Congreso de la República | F31: Congresista de la República | H31: Plaza Bolívar, Av. Abancay s/n, en el Cercado de Lima | I31: 2021 | J31: 2025 | K31: PERU | L31: LIMA | M31: LIMA | N31: LIMA | O31: Actualmente se desempeña como congresista de la república por el periodo legislativo 2021-2026 | P31: =IFERROR(__xludf.DUMMYFUNCTION("IF(REGEXMATCH(UPPER(E31),""CONGRESO""),1,0)"),1) -> 1
A32: FUERZA POPULAR | B32: 32971154 | C32: CHACON TRUJILLO, NILZA MERLY | D32: SI | E32: BOTICA ROMA | F32: Director Técnico - Químico Farmaceútico | H32: Av. Alberto Reyes 123-124 | I32: 2012 | J32: 2021 | K32: PERU | L32: ANCASH | M32: HUARMEY | N32: HUARMEY | P32: =IFERROR(__xludf.DUMMYFUNCTION("IF(REGEXMATCH(UPPER(E32),""CONGRESO""),1,0)"),0) -> 0
A33: FUERZA POPULAR | B33: 32971154 | C33: CHACON TRUJILLO, NILZA MERLY | D33: SI | E33: CONSTRUREDES | F33: Conductor de vehículo | H33: Alameda Premio Real Mz D, Lt. 10 | I33: 2019 | J33: 2021 | K33: PERU | L33: LIMA | M33: LIMA | N33: CHORRILLOS | P33: =IFERROR(__xludf.DUMMYFUNCTION("IF(REGEXMATCH(UPPER(E33),""CONGRESO""),1,0)"),0) -> 0
A34: FUERZA POPULAR | B34: 07960843 | C34: CHAVEZ COSSIO, MARTHA GLADYS | D34: SI | E34: Congreso de la República | F34: Congresista de la República | H34: Av. Abancay - Plaza Bolivar S/N | I34: 2011 | J34: 2016 | K34: PERU | L34: LIMA | M34: LIMA | N34: LIMA | P34: =IFERROR(__xludf.DUMMYFUNCTION("IF(REGEXMATCH(UPPER(E34),""CONGRESO""),1,0)"),1) -> 1
A35: FUERZA POPULAR | B35: 07960843 | C35: CHAVEZ COSSIO, MARTHA GLADYS | D35: SI | E35: Congreso de la República | F35: Congresista de la República | H35: Av. Abancay - Plaza Bolivar S/N | I35: 2020 | J35: 2021 | K35: PERU | L35: LIMA | M35: LIMA | N35: LIMA | O35: Fui congresista en el Congreso Complementario. | P35: =IFERROR(__xludf.DUMMYFUNCTION("IF(REGEXMATCH(UPPER(E35),""CONGRESO""),1,0)"),1) -> 1
A36: FUERZA POPULAR | B36: 07960843 | C36: CHAVEZ COSSIO, MARTHA GLADYS | D36: SI | E36: Congreso de la República | F36: Asesor | H36: Av. Abancay - Plaza Bolivar S/N | I36: 2016 | J36: 2020 | K36: PERU | L36: LIMA | M36: LIMA | N36: LIMA | P36: =IFERROR(__xludf.DUMMYFUNCTION("IF(REGEXMATCH(UPPER(E36),""CONGRESO""),1,0)"),1) -> 1
A37: FUERZA POPULAR | B37: 07960843 | C37: CHAVEZ COSSIO, MARTHA GLADYS | D37: SI | E37: Universidad Privada San Juan Bautista | F37: Docente | H37: Av. San Luis 1923 | I37: 2007 | J37: 2019 | K37: PERU | L37: LIMA | M37: LIMA | N37: LIMA | O37: He sido docente a tiempo parcial en la Escuela de Derecho. | P37: =IFERROR(__xludf.DUMMYFUNCTION("IF(REGEXMATCH(UPPER(E37),""CONGRESO""),1,0)"),0) -> 0
A38: FUERZA POPULAR | B38: 07960843 | C38: CHAVEZ COSSIO, MARTHA GLADYS | D38: SI | E38: Congreso de la República | F38: Asesor | H38: Av. Abancay - Plaza Bolivar S/N | I38: 2021 | J38: 2025 | K38: PERU | L38: LIMA | M38: LIMA | N38: LIMA | O38: Continúo laborando hasta la actualidad. | P38: =IFERROR(__xludf.DUMMYFUNCTION("IF(REGEXMATCH(UPPER(E38),""CONGRESO""),1,0)"),1) -> 1
A39: FUERZA POPULAR | B39: 05227631 | C39: DEL AGUILA CARDENAS, JUAN CARLOS | D39: SI | E39: CONGRESO DE LA REPUBLICA | F39: CONGRESISTA | H39: PLAZA BOLIVAR - AV ABANCAY | I39: 2016 | J39: 2019 | K39: PERU | L39: LIMA | M39: LIMA | N39: LIMA | O39: EL PERIODO DE ELECCION FUE DEL 2016 AL 2021, PERO FUE INTERRUMPIDO POR EL CIERRE INCONSTITUCIONAL DEL CONGRESO EL 30 DE SETIEMBRE DE 2019 | P39: =IFERROR(__xludf.DUMMYFUNCTION("IF(REGEXMATCH(UPPER(E39),""CONGRESO""),1,0)"),1) -> 1
A40: FUERZA POPULAR | B40: 05227631 | C40: DEL AGUILA CARDENAS, JUAN CARLOS | D40: SI | E40: AMAZONIA PRODUCCIONES E.I.R.L | F40: TITULAR GERENTE | H40: CALLE ATLANTIDA 741-821 | I40: 2022 | J40: 2025 | K40: PERU | L40: LORETO | M40: MAYNAS | N40: IQUITOS | P40: =IFERROR(__xludf.DUMMYFUNCTION("IF(REGEXMATCH(UPPER(E40),""CONGRESO""),1,0)"),0) -> 0
...

Sheet pivot_experiencia
A1: DNI_CANDIDATO | B1: TRABAJO ALGUNA VEZ EN CONGRESO | C1: REGISTROS CONGRESO
A2: 07755878 | B2: =IF(SUMIF('02 EXPERIENCIA LABORAL'!B:B,A2,'02 EXPERIENCIA LABORAL'!P:P)>0,1,0) -> 1 | C2: =SUMIF('02 EXPERIENCIA LABORAL'!B:B,A2,'02 EXPERIENCIA LABORAL'!P:P) -> 3
A3: 25331980 | B3: =IF(SUMIF('02 EXPERIENCIA LABORAL'!B:B,A3,'02 EXPERIENCIA LABORAL'!P:P)>0,1,0) -> 0 | C3: =SUMIF('02 EXPERIENCIA LABORAL'!B:B,A3,'02 EXPERIENCIA LABORAL'!P:P) -> 0
A4: 40204874 | B4: =IF(SUMIF('02 EXPERIENCIA LABORAL'!B:B,A4,'02 EXPERIENCIA LABORAL'!P:P)>0,1,0) -> 1 | C4: =SUMIF('02 EXPERIENCIA LABORAL'!B:B,A4,'02 EXPERIENCIA LABORAL'!P:P) -> 2
A5: 26705695 | B5: =IF(SUMIF('02 EXPERIENCIA LABORAL'!B:B,A5,'02 EXPERIENCIA LABORAL'!P:P)>0,1,0) -> 1 | C5: =SUMIF('02 EXPERIENCIA LABORAL'!B:B,A5,'02 EXPERIENCIA LABORAL'!P:P) -> 1
A6: 08236035 | B6: =IF(SUMIF('02 EXPERIENCIA LABORAL'!B:B,A6,'02 EXPERIENCIA LABORAL'!P:P)>0,1,0) -> 1 | C6: =SUMIF('02 EXPERIENCIA LABORAL'!B:B,A6,'02 EXPERIENCIA LABORAL'!P:P) -> 1
A7: 06717199 | B7: =IF(SUMIF('02 EXPERIENCIA LABORAL'!B:B,A7,'02 EXPERIENCIA LABORAL'!P:P)>0,1,0) -> 0 | C7: =SUMIF('02 EXPERIENCIA LABORAL'!B:B,A7,'02 EXPERIENCIA LABORAL'!P:P) -> 0
A8: 10307948 | B8: =IF(SUMIF('02 EXPERIENCIA LABORAL'!B:B,A8,'02 EXPERIENCIA LABORAL'!P:P)>0,1,0) -> 0 | C8: =SUMIF('02 EXPERIENCIA LABORAL'!B:B,A8,'02 EXPERIENCIA LABORAL'!P:P) -> 0
A9: 32971154 | B9: =IF(SUMIF('02 EXPERIENCIA LABORAL'!B:B,A9,'02 EXPERIENCIA LABORAL'!P:P)>0,1,0) -> 1 | C9: =SUMIF('02 EXPERIENCIA LABORAL'!B:B,A9,'02 EXPERIENCIA LABORAL'!P:P) -> 1
A10: 07960843 | B10: =IF(SUMIF('02 EXPERIENCIA LABORAL'!B:B,A10,'02 EXPERIENCIA LABORAL'!P:P)>0,1,0) -> 1 | C10: =SUMIF('02 EXPERIENCIA LABORAL'!B:B,A10,'02 EXPERIENCIA LABORAL'!P:P) -> 4
A11: 05227631 | B11: =IF(SUMIF('02 EXPERIENCIA LABORAL'!B:B,A11,'02 EXPERIENCIA LABORAL'!P:P)>0,1,0) -> 1 | C11: =SUMIF('02 EXPERIENCIA LABORAL'!B:B,A11,'02 EXPERIENCIA LABORAL'!P:P) -> 1
A12: 17896798 | B12: =IF(SUMIF('02 EXPERIENCIA LABORAL'!B:B,A12,'02 EXPERIENCIA LABORAL'!P:P)>0,1,0) -> 1 | C12: =SUMIF('02 EXPERIENCIA LABORAL'!B:B,A12,'02 EXPERIENCIA LABORAL'!P:P) -> 1
A13: 19994639 | B13: =IF(SUMIF('02 EXPERIENCIA LABORAL'!B:B,A13,'02 EXPERIENCIA LABORAL'!P:P)>0,1,0) -> 1 | C13: =SUMIF('02 EXPERIENCIA LABORAL'!B:B,A13,'02 EXPERIENCIA LABORAL'!P:P) -> 1
... A61: 31010129 | B61: =IF(SUMIF('02 EXPERIENCIA LABORAL'!B:B,A61,'02 EXPERIENCIA LABORAL'!P:P)>0,1,0) -> 0 | C61: =SUMIF('02 EXPERIENCIA LABORAL'!B:B,A61,'02 EXPERIENCIA LABORAL'!P:P) -> 0

Sheet 03 FORM ACADEM. - EDUC. BASICA
A1: ORGANIZACION_POLITICA | B1: DNI_CANDIDATO | C1: CANDIDATO | D1: TIENE_EDUCACION_BASICA | E1: EDUC_PRIMARIA | F1: EDUC_PRIMARIA_CONCLUIDA | G1: EDUC_SECUNDARIA | H1: EDUC_SECUNDARIA_CONCLUIDA
A2: AHORA NACION - AN | B2: 07755878 | C2: DELGADO ZEGARRA, JAIME RICARDO | D2: SI | E2: SI | F2: SI | G2: SI | H2: SI
A3: AHORA NACION - AN | B3: 25331980 | C3: LOPEZ CHAU NAVA, PABLO ALFONSO | D3: SI | E3: SI | F3: SI | G3: SI | H3: SI
A4: AHORA NACION - AN | B4: 25331980 | C4: LOPEZ CHAU NAVA, PABLO ALFONSO | D4: SI | E4: SI | F4: SI | G4: SI | H4: SI
A5: AHORA NACION - AN | B5: 40204874 | C5: LUQUE IBARRA, RUTH | D5: SI | E5: SI | F5: SI | G5: SI | H5: SI
A6: AHORA NACION - AN | B6: 26705695 | C6: VASQUEZ CHUQUILIN, MIRTHA ESTHER | D6: SI | E6: SI | F6: SI | G6: SI | H6: SI
A7: FUERZA POPULAR | B7: 08236035 | C7: AGUINAGA RECUENCO, ALEJANDRO AURELIO | D7: SI | E7: SI | F7: SI | G7: SI | H7: SI
A8: FUERZA POPULAR | B8: 06717199 | C8: ARISTA ARBILDO, JOSE BERLEY | D8: SI | E8: SI | F8: SI | G8: SI | H8: SI
A9: FUERZA POPULAR | B9: 10307948 | C9: ASTUDILLO SALCEDO, CESAR AUGUSTO | D9: SI | E9: SI | F9: SI | G9: SI | H9: SI
A10: FUERZA POPULAR | B10: 32971154 | C10: CHACON TRUJILLO, NILZA MERLY | D10: SI | E10: SI | F10: SI | G10: SI | H10: SI
A11: FUERZA POPULAR | B11: 07960843 | C11: CHAVEZ COSSIO, MARTHA GLADYS | D11: SI | E11: SI | F11: SI | G11: SI | H11: SI
A12: FUERZA POPULAR | B12: 05227631 | C12: DEL AGUILA CARDENAS, JUAN CARLOS | D12: SI | E12: SI | F12: SI | G12: SI | H12: SI
... A28: FUERZA POPULAR | B28: 21143880 | C28: VELASQUEZ PORTOCARRERO, JORGE | D28: SI | E28: SI | F28: SI | G28: SI | H28: SI
A29: FUERZA POPULAR | B29: 40242430 | C29: VENTURA ANGEL, HECTOR JOSE | D29: SI | E29: SI | G29: SI
A30: FUERZA POPULAR | B30: 21414172 | C30: YAMASHIRO ORE, RAFAEL GUSTAVO | D30: SI | E30: SI | F30: SI | G30: SI | H30: SI
A31: JUNTOS POR EL PERU | B31: 22482738 | C31: ANDRES LUJAN, SERAFIN | D31: SI | E31: SI | F31: SI | G31: SI | H31: SI
